Workbook

Sheet New process flow
B1: High aspect ratio process development project
A2: step | B2: Tool | C2: Recipe | D2: Notes | E2: Purpose
A3: 1. Drop gauge | B3: Drop gauge | D3: Measure just outside C,N,E,S,W features
A4: 2. Ash | B4: YES asher | C4: Recipe 4 Descum | D4: Ash immediately prior to deposition | E4: Wafer clean
A5: 3. Oxide | B5: PECVD2 | C5: USER_SiO2_350_6u | D5: 32 min for single wafer, 43 min for wafer + afterclean | E5: Hard mask for DRIE etch
A6: 4. Drop gauge/Filmmetrics | B6: Drop gauge | D6: Measure just outside C,N,E,S,W features. Filmmetrics is a more accurate way to measure oxide thickness especially when oxide thickness is <5 um. | E6: measure oxide thickness
A7: 5. Ash | B7: YES asher | C7: Recipe 4 Descum | D7: Ash immediately prior to coating | E7: Improve resist adhesion
A8: 6. Coat | B8: Rite Track (coater side) | C8: talk to Jean | D8: AZ10XT, 9 um | E8: HMDS, coat, bake to deposit photoresist
A9: 6.1 EBR | B9: Rite Track (coater side) | C9: talk to Jean | E9: remove edge bead for ICP-F
A10: 6.2 Rehydrate | C10: 30 min | E10: Important!!! Don't skip this step otherwise photoresist will crack post develop
A11: 7. Drop gauge | B11: Drop gauge | D11: Measure just outside C,N,E,S,W features | E11: measure resist thickness
A12: 8. Expose | B12: ABM | C12: HAR DRIE mask | D12: 84s total, split into two 42 second intervals with at least 30s inbetween exposure. | E12: Expose test pattern into resist
A13: 9. Develop | B13: Rite Track (developer Track) | C13: DEV6 | E13: Dissolve exposed regions of resist in developer to transfer mask pattern into resist
A14: 10. Inspect | B14: NIKON | D14: Check for completed develop and flaws (NOTE: features with sizes less than 3um may not resolve.) | E14: Visually confirm exposure and development of resist
A15: 11. Ash | B15: YES asher | C15: Recipe 4 Descum | E15: cleans remnants of exposed-yet-undeveloped resist via a low-power oxygen plasma
A16: 12. Etch oxide hardmask | B16: ICP-F | C16: QT SiO2 Etch-C4F8/O2 20C 5mT, 10.5 min | E16: Removal of oxide layer in exposed areas
A17: 13. Drop gauge | B17: Drop gauge | D17: Measure just outside C,N,E,S,W features | E17: measure remaining resist thickness
A18: 14. Keyence | B18: Keyence | D18: Measure trench and hole depths of C,N,E,S,W features
A19: 14.1 SEM * | B19: SEM | C19: may not be necessary depending on if keyence works | D19: Sacrifice 1 wafer, cut across features, Do cross-section SEM with 45 degree angle stage, coat gold (Au/Pd recipe 30 sec) to minimize charging effect | E19: verify side wall profile of resist, SiO2 fully etched in trenches
A20: 15. SPTS-DRIE DOE etch | B20: SPTS-DRIE | C20: See SPTS-DRIE tab
A21: 16. Drop gauge | B21: Drop gauge | D21: Measure just outside C,N,E,S,W features | E21: measure remaining mask thickness
A22: 17. SEM | B22: SEM | D22: Sacrifice 1 wafer, cut across features, Do cross-section SEM with 45 degree angle stage, coat gold (Au/Pd recipe 30 sec) to minimize charging effect | E22: Check etch depth, side wall profile etc.

Sheet batch 3 data
A1: Wafer | D1: 1. Drop gauge | K1: 4. Drop gauge | R1: 7. Drop gauge | Y1: 10. Inspect | Z1: 13. Drop gauge | AG1: 14. Keyence (5um depths) | AN1: 16. Drop gauge | AU1: 17. SEM | BA1: Scaled trench depth | BD1: Etch Rate | BE1: Erosion | BF1: Selectivity | BG1: Aspect Ratio
B2: Completed | C2: Next Step | D2: C | E2: N (major flat) | F2: E | G2: S | H2: W | I2: Mean | J2: U | K2: C | L2: N (major flat) | M2: E | N2: S | O2: W | P2: Mean | Q2: U | R2: C | S2: N (major flat) | T2: E | U2: S | V2: W | W2: Mean | X2: U | Y2: Notes | Z2: C | AA2: N (major flat) | AB2: E | AC2: S | AD2: W | AE2: Mean | AF2: U | AG2: C | AH2: N (major flat) | AI2: E | AJ2: S | AK2: W | AL2: Mean | AM2: U | AN2: C | AO2: N (major flat) | AP2: E | AQ2: S | AR2: W | AS2: Mean | AT2: U | AU2: Feature | AV2: Wafer thickness | AW2: 5um trench depth | AX2: 3um trench depth | AY2: 1um trench depth | AZ2: Comments | BA2: 5 um | BB2: 3 um | BC2: 1 um | BD2: um/loop (Si) | BE2: um/loop (SiO2) | BF2: (SiO2/Si) | BG2: (W/D)
A3: B01 | B3: 4. Drop gauge | C3: 5. Ash | D3: 518.14 | E3: 518.88 | F3: 518.31 | G3: 516.96 | H3: 518.94 | I3: =AVERAGE(D3:H3) -> 518.246 | J3: =(MAX(D3:H3)-MIN(D3:H3))/(2*I3) -> 0.0019102897 | K3: 524.37 | L3: 525.63 | M3: 525.03 | N3: 523.47 | O3: 524.6 | P3: =AVERAGE(K3:O3) -> 524.62 | Q3: =(MAX(K3:O3)-MIN(K3:O3))/(2*P3) -> 0.0020586329
A4: B02 | B4: 4. Drop gauge | C4: 5. Ash | D4: 518.8 | E4: 519.63 | F4: 518.6 | G4: 517.57 | H4: 518.81 | I4: =AVERAGE(D4:H4) -> 518.682 | J4: =(MAX(D4:H4)-MIN(D4:H4))/(2*I4) -> 0.0019858025 | K4: 525.16 | L4: 526.76 | M4: 524.93 | N4: 523.5 | O4: 525.26 | P4: =AVERAGE(K4:O4) -> 525.122 | Q4: =(MAX(K4:O4)-MIN(K4:O4))/(2*P4) -> 0.0031040406
A5: B03 | B5: 4. Drop gauge | C5: 5. Ash | D5: 519.47 | E5: 520.14 | F5: 519.07 | G5: 517.83 | H5: 519.8 | I5: =AVERAGE(D5:H5) -> 519.262 | J5: =(MAX(D5:H5)-MIN(D5:H5))/(2*I5) -> 0.0022243107 | K5: 525.4 | L5: 526.78 | M5: 525.25 | N5: 523.94 | O5: 526.42 | P5: =AVERAGE(K5:O5) -> 525.558 | Q5: =(MAX(K5:O5)-MIN(K5:O5))/(2*P5) -> 0.0027018902
A6: B04 | B6: 4. Drop gauge | C6: 5. Ash | D6: 519.34 | E6: 521.44 | F6: 519.22 | G6: 517.61 | H6: 518.87 | I6: =AVERAGE(D6:H6) -> 519.296 | J6: =(MAX(D6:H6)-MIN(D6:H6))/(2*I6) -> 0.0036876849 | K6: 525.66 | L6: 527 | M6: 526.18 | N6: 524.14 | O6: 525.98 | P6: =AVERAGE(K6:O6) -> 525.792 | Q6: =(MAX(K6:O6)-MIN(K6:O6))/(2*P6) -> 0.0027197067
A7: B05 | B7: 4. Drop gauge | C7: 5. Ash | D7: 518.09 | E7: 518.04 | F7: 518.07 | G7: 515.21 | H7: 517.11 | I7: =AVERAGE(D7:H7) -> 517.304 | J7: =(MAX(D7:H7)-MIN(D7:H7))/(2*I7) -> 0.002783663 | K7: 523.5 | L7: 523.68 | M7: 523.18 | N7: 522.83 | O7: 523.86 | P7: =AVERAGE(K7:O7) -> 523.41 | Q7: =(MAX(K7:O7)-MIN(K7:O7))/(2*P7) -> 0.00098393229
A8: B06 | B8: 4. Drop gauge | C8: 5. Ash | D8: 517.34 | E8: 517.49 | F8: 517.25 | G8: 516.45 | H8: 517.74 | I8: =AVERAGE(D8:H8) -> 517.254 | J8: =(MAX(D8:H8)-MIN(D8:H8))/(2*I8) -> 0.0012469696 | K8: 523.98 | L8: 524.18 | M8: 524.35 | N8: 522.62 | O8: 523.4 | P8: =AVERAGE(K8:O8) -> 523.706 | Q8: =(MAX(K8:O8)-MIN(K8:O8))/(2*P8) -> 0.0016516901
A9: B07 | B9: 4. Drop gauge | C9: 5. Ash | D9: 521.85 | E9: 520.89 | F9: 519.63 | G9: 517.77 | H9: 519.48 | I9: =AVERAGE(D9:H9) -> 519.924 | J9: =(MAX(D9:H9)-MIN(D9:H9))/(2*I9) -> 0.0039236504 | K9: 529.22 | L9: 528.38 | M9: 527.17 | N9: 525.26 | O9: 526.67 | P9: =AVERAGE(K9:O9) -> 527.34 | Q9: =(MAX(K9:O9)-MIN(K9:O9))/(2*P9) -> 0.0037546934
A10: B08 | B10: 3. Oxide | C10: 4. Drop gauge | D10: 519.02 | E10: 519.86 | F10: 518.36 | G10: 517.5 | H10: 519.45 | I10: =AVERAGE(D10:H10) -> 518.838 | J10: =(MAX(D10:H10)-MIN(D10:H10))/(2*I10) -> 0.002274313
A11: B09 | B11: 3. Oxide | C11: 4. Drop gauge | D11: 522.76 | E11: 522.45 | F11: 522.56 | G11: 521.49 | H11: 522.78 | I11: =AVERAGE(D11:H11) -> 522.408 | J11: =(MAX(D11:H11)-MIN(D11:H11))/(2*I11) -> 0.0012346672
A12: B10 | B12: 3. Oxide | C12: 4. Drop gauge | D12: 523.01 | E12: 522.4 | F12: 522.3 | G12: 521.7 | H12: 522.75 | I12: =AVERAGE(D12:H12) -> 522.432 | J12: =(MAX(D12:H12)-MIN(D12:H12))/(2*I12) -> 0.0012537517
A13: B11 | B13: 1. Drop gauge | C13: 2. Ash | D13: 522.69 | E13: 522.45 | F13: 522.74 | G13: 522.25 | H13: 522.79 | I13: =AVERAGE(D13:H13) -> 522.584 | J13: =(MAX(D13:H13)-MIN(D13:H13))/(2*I13) -> 0.00051666335
A14: B12 | B14: 1. Drop gauge | C14: 2. Ash | D14: 524.18 | E14: 524.24 | F14: 524.5 | G14: 522.75 | H14: 523.72 | I14: =AVERAGE(D14:H14) -> 523.878 | J14: =(MAX(D14:H14)-MIN(D14:H14))/(2*I14) -> 0.0016702362
K16: Oxide dep:
K17: C | L17: N | M17: E | N17: S | O17: W | P17: Mean | Q17: U
J18: B01 | K18: =K3-D3 -> 6.23 | L18: =L3-E3 -> 6.75 | M18: =M3-F3 -> 6.72 | N18: =N3-G3 -> 6.51 | O18: =O3-H3 -> 5.66 | P18: =AVERAGE(K18:O18) -> 6.374 | Q18: =(MAX(K18:O18)-MIN(K18:O18))/(2*P18) -> 0.085503608
J19: B02 | K19: =K4-D4 -> 6.36 | L19: =L4-E4 -> 7.13 | M19: =M4-F4 -> 6.33 | N19: =N4-G4 -> 5.93 | O19: =O4-H4 -> 6.45 | P19: =AVERAGE(K19:O19) -> 6.44 | Q19: =(MAX(K19:O19)-MIN(K19:O19))/(2*P19) -> 0.093167702
J20: B03 | K20: =K5-D5 -> 5.93 | L20: =L5-E5 -> 6.64 | M20: =M5-F5 -> 6.18 | N20: =N5-G5 -> 6.11 | O20: =O5-H5 -> 6.62 | P20: =AVERAGE(K20:O20) -> 6.296 | Q20: =(MAX(K20:O20)-MIN(K20:O20))/(2*P20) -> 0.056385006
J21: B04 | K21: =K6-D6 -> 6.32 | L21: =L6-E6 -> 5.56 | M21: =M6-F6 -> 6.96 | N21: =N6-G6 -> 6.53 | O21: =O6-H6 -> 7.11 | P21: =AVERAGE(K21:O21) -> 6.496 | Q21: =(MAX(K21:O21)-MIN(K21:O21))/(2*P21) -> 0.11930419
J22: B05 | K22: =K7-D7 -> 5.41 | L22: =L7-E7 -> 5.64 | M22: =M7-F7 -> 5.11 | N22: =N7-G7 -> 7.62 | O22: =O7-H7 -> 6.75 | P22: =AVERAGE(K22:O22) -> 6.106 | Q22: =(MAX(K22:O22)-MIN(K22:O22))/(2*P22) -> 0.20553554
J23: B06 | K23: =K8-D8 -> 6.64 | L23: =L8-E8 -> 6.69 | M23: =M8-F8 -> 7.1 | N23: =N8-G8 -> 6.17 | O23: =O8-H8 -> 5.66 | P23: =AVERAGE(K23:O23) -> 6.452 | Q23: =(MAX(K23:O23)-MIN(K23:O23))/(2*P23) -> 0.1115933
J24: B07 | K24: =K9-D9 -> 7.37 | L24: =L9-E9 -> 7.49 | M24: =M9-F9 -> 7.54 | N24: =N9-G9 -> 7.49 | O24: =O9-H9 -> 7.19 | P24: =AVERAGE(K24:O24) -> 7.416 | Q24: =(MAX(K24:O24)-MIN(K24:O24))/(2*P24) -> 0.023597627
J25: B08
J26: B09
J27: B10
J28: B11
J29: B12
K31: Oxide dep Filmetrics:
K32: Min | L32: Max | M32: Mean | N32: Std. Dev. | O32: Unif. [%]
J33: B01 | K33: 5.872 | L33: 6.092 | M33: 5.941 | N33: 0.04783 | O33: 1.8
J34: B02 | K34: 5.951 | L34: 6.158 | M34: 6.014 | N34: 0.04488 | O34: 1.7
J35: B03 | K35: 5.922 | L35: 6.147 | M35: 6.001 | N35: 0.04851 | O35: 1.9
J36: B04 | K36: 5.892 | L36: 6.113 | M36: 5.964 | N36: 0.04743 | O36: 1.9
J37: B05 | K37: 5.939 | L37: 6.164 | M37: 6.02 | N37: 0.04869 | O37: 1.9
J38: B06 | K38: 5.935 | L38: 6.165 | M38: 6.022 | N38: 0.04971 | O38: 1.9
J39: B07 | K39: 5.894 | L39: 6.106 | M39: 5.956 | N39: 0.0454 | O39: 1.8
J40: B08 | K40: 5.967 | L40: 6.185 | M40: 6.041 | N40: 0.04728 | O40: 1.8
J41: B09 | K41: 5.976 | L41: 6.187 | M41: 6.042 | N41: 0.04596 | O41: 1.8
J42: B10 | K42: 5.943 | L42: 6.162 | M42: 6.017 | N42: 0.04754 | O42: 1.8
...

Sheet ICP-F
A1: Run | B1: wafer # | C1: Date | D1: Recipe | E1: Etch time (min) | F1: Batches/loops | G1: DC bias jump time | H1: He flow
A2: 1 | B2: A2 | D2: QT SiO2 Etch-C4F8/O2 | E2: 15 | F2: 2
A3: 2 | B3: A3 | D3: QT SiO2 Etch-C4F8/O2 | E3: 12 | F3: 2
A4: 3 | B4: A4 | D4: QT SiO2 Etch-C4F8/O2 | E4: 10.5 | F4: 2
A5: 4 | B5: A5 | D5: QT SiO2 Etch-C4F8/O2 | E5: 10.5 | F5: 2
A6: 5 | B6: A6 | D6: QT SiO2 Etch-C4F8/O2 | E6: 10.5 | F6: 2
A7: 6 | B7: A7 | D7: QT SiO2 Etch-C4F8/O2 | E7: 10.5 | F7: 2
A8: 7 | B8: A8 | D8: QT SiO2 Etch-C4F8/O2 | E8: 10.5 | F8: 2
A9: 8 | B9: A9 | D9: QT SiO2 Etch-C4F8/O2 | E9: 10.5 | F9: 2
A10: 9 | B10: A10 | D10: QT SiO2 Etch-C4F8/O2 | E10: 10.5 | F10: 2
A11: 10 | B11: A11 | D11: QT SiO2 Etch-C4F8/O2 | E11: 10.5 | F11: 2
A12: 11 | B12: A12 | D12: QT SiO2 Etch-C4F8/O2 | E12: 10.5 | F12: 2
A13: 12 | B13: A13 | D13: QT SiO2 Etch-C4F8/O2 | E13: 10.5 | F13: 2
... A16: 15 | B16: A16 | D16: QT SiO2 Etch-C4F8/O2 | E16: 10.5 | F16: 3
A17: 16 | B17: B01 | E17: 15 | F17: 15

Sheet SPTS-DRIE
A1: Run | B1: wafer # | C1: Date | D1: Seq | E1: Recipe | F1: He flow at loop 10 | G1: He flow at loop 300 | H1: He flow at the end | I1: Max reflect. power 2 at loop 10 | J1: Max reflect. power 2 at loop 300 | K1: Max reflect. power 2 at the end | L1: Loop set 1: | M1: Loop set 2: | N1: Loop set 3:
A2: 1 | B2: A5 | C2: 45670 | D2: MM_Deep_STD_-3seq | E2: MM_Deep_Standard_-3 | F2: 14.2 sccm | G2: 14.5 sccm | H2: 14.9 sccm | L2: 500
A3: 2 | B3: A6 | C3: 45686 | D3: MM_Deep_3x_-3seq | E3: MM_Deep_3X_-3 | F3: 13.6 sccm | G3: 14.2 sccm | L3: 262 | M3: 483 | N3: 200
A4: 3 | B4: A7 | C4: 45709 | D4: MM_Deep_3x_-3seq | E4: MM_Deep_3X_-3 | F4: 17.0 sccm | G4: 18.6 sccm | L4: 262 | M4: 165 | N4: 0
A5: 4 | B5: A7.2 | C5: 45709 | D5: MM_Deep_3x_-3seq | E5: MM_Deep_3X_-3 | F5: 15.6 sccm | G5: 16.4 sccm | H5: 17.0 sccm | L5: 1 | M5: 318 | N5: 300
A6: 5 | B6: A7b | C6: 45714 | D6: MM_Deep_3x_-3seq | E6: MM_Deep_3X_-3 | F6: 17.0 sccm | H6: 17.5 sccm | L6: 1 | M6: 1 | N6: 200
A7: 6 | B7: A7c | C7: 45714 | D7: MM_Deep_3x_-3seq | E7: MM_Deep_3X_-3 | F7: 17.0 sccm | H7: 16.9 sccm | L7: 1 | M7: 1 | N7: 150
A8: 7 | B8: A8 | C8: 45716 | D8: MM_Deep_3xwC_-3seq | E8: MM_Deep_3XwC_-3 | F8: 16.5 sccm | G8: 16.7 sccm | H8: 18.3 sccm | I8: 185 W | J8: 204 W | K8: 198 W | L8: 262 | M8: 483 | N8: 550
A9: 8 | B9: A9 | C9: 45720 | D9: MD_DOE4_3x_-3seq | E9: MD_DOE4_3x_-3 | F9: 17.1 sccm | H9: 17.1 sccm | I9: 226 W | K9: 209 W | L9: 1 | M9: 1 | N9: 20
A10: 9 | B10: A10 | C10: 45720 | D10: MD_DOE2_3x_-3seq | E10: MD_DOE2_3x_-3 | F10: 16.5 sccm | G10: 16.8 sccm | H10: 18.2 sccm | I10: 196 W | J10: 183 W | K10: 206 W | L10: 262 | M10: 483 | N10: 550
A11: 10 | B11: A11 | C11: 45721 | D11: MD_DOE1_3x_-3seq | E11: MD_DOE1_3x_-3 | F11: 18.2 sccm | G11: 19.5 sccm | H11: 20.0 sccm | I11: 194 W | J11: 186 W | K11: 174 W | L11: 262 | M11: 192 | N11: 0
A12: 11 | B12: A11b | C12: 45721 | D12: MD_DOE1_3x_-3seq | E12: MD_DOE1_3x_-3 | F12: 18.1 sccm | G12: 19.3 sccm | H12: 20.0 sccm | I12: 189 W | J12: 215 W | K12: 239 W | L12: 1 | M12: 291 | N12: 272
A13: 12 | B13: A12 | C13: 45722 | D13: MD_DOE7_3x_-3seq | E13: MD_DOE7_3x_-3 | F13: 20.0 sccm | L13: 2 | M13: 0 | N13: 0
A14: 13 | B14: A13 | C14: 45722 | D14: MD_DOE7_3x_-3seq | E14: MD_DOE7_3x_-3 | F14: 20.0 sccm | L14: 4 | M14: 0 | N14: 0
A15: 14 | B15: A11c | C15: 45724 | D15: MD_DOE1_3x_-3seq | E15: MD_DOE1_3x_-3 | F15: 17.8 sccm | H15: 17.9 sccm | I15: 214 W | K15: 223 W | L15: 1 | M15: 1 | N15: 278
A16: 15 | B16: A13 | C16: 45724 | D16: MD_DOE7_3x_-3seq | E16: MD_DOE7_3x_-3 | F16: 17.3 sccm | G16: 17.7 sccm | H16: 18.7 sccm | I16: 200 W | J16: 179 W | K16: 239 W | L16: 258 | M16: 483 | N16: 550
A17: 16 | B17: A9 | C17: 45726 | D17: MD_DOE3_3x_-3seq | E17: MD_DOE3_3x_-3 | F17: 17.6 sccm | G17: 18.1 sccm | H17: 18.7 sccm | I17: 183 W | J17: 185 W | K17: 177 W | L17: 240 | M17: 483 | N17: 550
A18: 17 | B18: A15 | C18: 45727 | D18: MD_DOE4_3x_-3seq | E18: MD_DOE4_3x_-3 | F18: 18.2 sccm | G18: 18.8 sccm | H18: 20.0 sccm | I18: 192 W | J18: 191 W | K18: 176 W | L18: 262 | M18: 478 | N18: 0
A19: 18 | B19: A12 | C19: 45729 | D19: MD_DOE5_3x_-3seq | E19: MD_DOE5_3x_-3 | F19: 17.5 sccm | G19: 17.8 sccm | H19: 18.5 sccm | I19: 193 W | J19: 204 W | K19: 178 W | L19: 260 | M19: 483 | N19: 550
A20: 19 | B20: A16 | C20: 45730 | D20: MD_DOE8_3x_-3seq | E20: MD_DOE8_3x_-3 | F20: 16.9 sccm | G20: 17.5 sccm | H20: 18.0 sccm | I20: 201 W | J20: 195 W | K20: 175 W | L20: 262 | M20: 483 | N20: 550
A21: 20 | B21: A15 | C21: 45732 | D21: MD_DOE6_3x_-3seq | E21: MD_DOE6_3x_-3 | F21: 16.1 sccm | G21: 16.8 sccm | H21: 16.4 sccm | I21: 181 W | J21: 167 W | K21: 173 W | L21: 0 | M21: 5 | N21: 550
A22: 21 | B22: A14 | C22: 45732 | D22: MD_DOE4_3x_-3seq | E22: MD_DOE4_3x_-3 | F22: 15.8 sccm | G22: 16.6 sccm | H22: 15.7 sccm | I22: 196 W | J22: 180 W | K22: 240 W | L22: 262 | M22: 483 | N22: 550

Sheet 5 um depth
A1: Drop gauge: | C1: Keyence: | D1: 500 | E1: 200 | F1: 100 | G1: SEM50: | H1: 500 | I1: 200 | J1: 100 | K1: 50 | L1: 25 | M1: 15 | N1: 10 | O1: 5 | P1: Drop gauge scaled: | Q1: 500 | R1: 200 | S1: 100 | T1: 50 | U1: 25 | V1: 15 | W1: 10 | X1: 5 | Y1: Keyence scaled: | Z1: 500 | AA1: 200 | AB1: 100 | AC1: 50 | AD1: 25 | AE1: 15 | AF1: 10 | AG1: 5 | AH1: SEM200+ | AI1: 10 | AJ1: 5 | AK1: Pseudo-depth: | AL1: 5
A2: A9S | B2: ='Drop gauge'!D5 -> 1019.9 | C2: A9S | D2: ='DOE data'!BB5 -> 741.9 | E2: ='DOE data'!BG5 -> 688.1 | F2: ='DOE data'!BL5 -> 579.1 | G2: 1087.5 | H2: 753.8 | I2: 716.3 | J2: 615 | K2: 513.8 | L2: 373.1 | M2: 153.8 | N2: 121.9 | O2: 131.3 | P2: =G2/B2 -> 1.066281 | Q2: =H2/$P2 -> 706.9431 | R2: =I2/$P2 -> 671.77413 | S2: =J2/$P2 -> 576.77103 | T2: =K2/$P2 -> 481.86172 | U2: =L2/$P2 -> 349.90776 | V2: =M2/$P2 -> 144.23965 | W2: =N2/$P2 -> 114.32258 | X2: =O2/$P2 -> 123.13827 | Y2: =AVERAGE(H2/D2,I2/E2,J2/F2) -> 1.0396717 | Z2: =H2/$Y2 -> 725.03658 | AA2: =I2/$Y2 -> 688.9675 | AB2: =J2/$Y2 -> 591.53289 | AC2: =K2/$Y2 -> 494.19447 | AD2: =L2/$Y2 -> 358.86329 | AE2: =M2/$Y2 -> 147.93132 | AF2: =N2/$Y2 -> 117.24855 | AG2: =O2/$Y2 -> 126.28987 | AI2: 118.84 | AJ2: 127.45 | AK2: A9S | AL2: =X2+'Drop gauge'!D14 -> 128.23827
A3: A10S | B3: ='Drop gauge'!D6 -> 1012.7 | C3: A10S | D3: ='DOE data'!BB6 -> 817.7 | E3: ='DOE data'!BG6 -> 724.9 | F3: ='DOE data'!BL6 -> 635 | G3: 1061.3 | H3: 813.8 | I3: 768.8 | J3: 684.4 | K3: 581.3 | L3: 457.5 | M3: 373.1 | N3: 296.3 | O3: 226.9 | P3: =G3/B3 -> 1.0479905 | Q3: =H3/$P3 -> 776.53374 | R3: =I3/$P3 -> 733.59442 | S3: =J3/$P3 -> 653.05934 | T3: =K3/$P3 -> 554.68059 | U3: =L3/$P3 -> 436.54975 | V3: =M3/$P3 -> 356.01467 | W3: =N3/$P3 -> 282.73157 | X3: =O3/$P3 -> 216.50959 | Y3: =AVERAGE(H3/D3,I3/E3,J3/F3) -> 1.0445286 | Z3: =H3/$Y3 -> 779.10742 | AA3: =I3/$Y3 -> 736.02578 | AB3: =J3/$Y3 -> 655.22379 | AC3: =K3/$Y3 -> 556.51897 | AD3: =L3/$Y3 -> 437.99661 | AE3: =M3/$Y3 -> 357.19461 | AF3: =N3/$Y3 -> 283.66863 | AG3: =O3/$Y3 -> 217.22717 | AI3: 285.5 | AJ3: 227.8 | AK3: A10S | AL3: =X3 -> 216.50959
A4: A11S | B4: ='Drop gauge'!D7 -> 1019 | C4: A11S | D4: ='DOE data'!BB7 -> 831.2 | E4: ='DOE data'!BG7 -> 746.3 | F4: ='DOE data'!BL7 -> 656 | G4: 1076.3 | H4: 817.5 | I4: 778.1 | J4: 690 | K4: 594.4 | L4: 480 | M4: 399.4 | N4: 339.4 | O4: 311.3 | P4: =G4/B4 -> 1.0562316 | Q4: =H4/$P4 -> 773.97798 | R4: =I4/$P4 -> 736.67556 | S4: =J4/$P4 -> 653.26582 | T4: =K4/$P4 -> 562.75537 | U4: =L4/$P4 -> 454.44579 | V4: =M4/$P4 -> 378.13676 | W4: =N4/$P4 -> 321.33104 | X4: =O4/$P4 -> 294.72703 | Y4: =AVERAGE(H4/D4,I4/E4,J4/F4) -> 1.0259858 | Z4: =H4/$Y4 -> 796.79468 | AA4: =I4/$Y4 -> 758.39259 | AB4: =J4/$Y4 -> 672.52395 | AC4: =K4/$Y4 -> 579.34527 | AD4: =L4/$Y4 -> 467.84275 | AE4: =M4/$Y4 -> 389.28415 | AF4: =N4/$Y4 -> 330.80381 | AG4: =O4/$Y4 -> 303.41552 | AI4: 333.8 | AJ4: 304.2 | AK4: A11S | AL4: =X4 -> 294.72703
A5: A12C | B5: ='Drop gauge'!B8 -> 998.4 | C5: A12C | D5: ='DOE data'!BA8 -> 730.6 | E5: ='DOE data'!BF8 -> 653.1 | F5: ='DOE data'!BK8 -> 567.7 | G5: 1061.3 | H5: 740.6 | I5: 705 | J5: 615 | K5: 521.3 | L5: 414.4 | M5: 341.3 | N5: 281.3 | O5: 251.3 | P5: =G5/B5 -> 1.0630008 | Q5: =H5/$P5 -> 696.70691 | R5: =I5/$P5 -> 663.21681 | S5: =J5/$P5 -> 578.55083 | T5: =K5/$P5 -> 490.40415 | U5: =L5/$P5 -> 389.83978 | V5: =M5/$P5 -> 321.07219 | W5: =N5/$P5 -> 264.62821 | X5: =O5/$P5 -> 236.40622 | Y5: =AVERAGE(H5/D5,I5/E5,J5/F5) -> 1.0588244 | Z5: =H5/$Y5 -> 699.45498 | AA5: =I5/$Y5 -> 665.83279 | AB5: =J5/$Y5 -> 580.83286 | AC5: =K5/$Y5 -> 492.33849 | AD5: =L5/$Y5 -> 391.37746 | AE5: =M5/$Y5 -> 322.33862 | AF5: =N5/$Y5 -> 265.672 | AG5: =O5/$Y5 -> 237.33869 | AI5: 275.6 | AJ5: 245.6 | AK5: A12C | AL5: =X5 -> 236.40622
A6: A13S | B6: ='Drop gauge'!D9 -> 1017.1 | C6: A13S | D6: ='DOE data'!BB9 -> 816.5 | E6: ='DOE data'!BG9 -> 732.3 | F6: ='DOE data'!BL9 -> 638.3 | G6: 1083.8 | H6: 828.8 | I6: 787.6 | J6: 686.3 | K6: 581.3 | L6: 453.9 | M6: 363.8 | N6: 258.8 | O6: 180 | P6: =G6/B6 -> 1.0655786 | Q6: =H6/$P6 -> 777.79339 | R6: =I6/$P6 -> 739.12895 | S6: =J6/$P6 -> 644.06323 | T6: =K6/$P6 -> 545.52522 | U6: =L6/$P6 -> 425.96576 | V6: =M6/$P6 -> 341.41076 | W6: =N6/$P6 -> 242.87274 | X6: =O6/$P6 -> 168.92231 | Y6: =AVERAGE(H6/D6,I6/E6,J6/F6) -> 1.0552598 | Z6: =H6/$Y6 -> 785.39897 | AA6: =I6/$Y6 -> 746.35645 | AB6: =J6/$Y6 -> 650.36114 | AC6: =K6/$Y6 -> 550.85958 | AD6: =L6/$Y6 -> 430.13102 | AE6: =M6/$Y6 -> 344.74921 | AF6: =N6/$Y6 -> 245.24765 | AG6: =O6/$Y6 -> 170.5741 | AI6: 253.6 | AJ6: 174.8 | AK6: A13S | AL6: =X6 -> 168.92231
A7: A14C | B7: ='Drop gauge'!B10 -> 929.82 | C7: A14C | D7: ='DOE data'!BA10 -> 697.1 | E7: ='DOE data'!BF10 -> 610.3 | F7: ='DOE data'!BK10 -> 515.7 | G7: 969.4 | H7: 720 | I7: 631.9 | J7: 543.8 | K7: 444.4 | L7: 311.3 | M7: 221.3 | N7: 120 | O7: 82.5 | P7: =G7/B7 -> 1.0425674 | Q7: =H7/$P7 -> 690.60285 | R7: =I7/$P7 -> 606.09992 | S7: =J7/$P7 -> 521.59698 | T7: =K7/$P7 -> 426.25542 | U7: =L7/$P7 -> 298.58981 | V7: =M7/$P7 -> 212.26446 | W7: =N7/$P7 -> 115.10047 | X7: =O7/$P7 -> 79.131576 | Y7: =AVERAGE(H7/D7,I7/E7,J7/F7) -> 1.0409106 | Z7: =H7/$Y7 -> 691.70204 | AA7: =I7/$Y7 -> 607.06461 | AB7: =J7/$Y7 -> 522.42718 | AC7: =K7/$Y7 -> 426.93387 | AD7: =L7/$Y7 -> 299.06506 | AE7: =M7/$Y7 -> 212.60231 | AF7: =N7/$Y7 -> 115.28367 | AG7: =O7/$Y7 -> 79.257526 | AI7: 115.8 | AJ7: 79.2 | AK7: A14C | AL7: =X7+'Drop gauge'!B19 -> 176.21158
A8: A15S | B8: ='Drop gauge'!D11 -> 971.38 | C8: A15S | D8: ='DOE data'!BB11 -> 704.6 | E8: ='DOE data'!BG11 -> 633.3 | F8: ='DOE data'!BL11 -> 551.2 | G8: 1042.5 | H8: 710.6 | I8: 684.4 | J8: 596.3 | K8: 515.6 | L8: 401.3 | M8: 337.5 | N8: 277.5 | O8: 253.1 | P8: =G8/B8 -> 1.0732154 | Q8: =H8/$P8 -> 662.12242 | R8: =I8/$P8 -> 637.70981 | S8: =J8/$P8 -> 555.62004 | T8: =K8/$P8 -> 480.42545 | U8: =L8/$P8 -> 373.92306 | V8: =M8/$P8 -> 314.47554 | W8: =N8/$P8 -> 258.56878 | X8: =O8/$P8 -> 235.83336 | Y8: =AVERAGE(H8/D8,I8/E8,J8/F8) -> 1.0570085 | Z8: =H8/$Y8 -> 672.27465 | AA8: =I8/$Y8 -> 647.48772 | AB8: =J8/$Y8 -> 564.13928 | AC8: =K8/$Y8 -> 487.79174 | AD8: =L8/$Y8 -> 379.65637 | AE8: =M8/$Y8 -> 319.29735 | AF8: =N8/$Y8 -> 262.53337 | AG8: =O8/$Y8 -> 239.44936 | AI8: 274.2 | AJ8: 248.4 | AK8: A15S | AL8: =X8+'Drop gauge'!D20 -> 289.45336
A9: A16C | B9: ='Drop gauge'!B12 -> 1022.5 | C9: A16C | D9: ='DOE data'!BA12 -> 738.4 | E9: ='DOE data'!BF12 -> 662.4 | F9: ='DOE data'!BK12 -> 578.6 | G9: 1095 | H9: 753.8 | I9: 714.4 | J9: 624.4 | K9: 540 | L9: 431.3 | M9: 352.5 | N9: 290.6 | O9: 255 | P9: =G9/B9 -> 1.0709046 | Q9: =H9/$P9 -> 703.89087 | R9: =I9/$P9 -> 667.09954 | S9: =J9/$P9 -> 583.05845 | T9: =K9/$P9 -> 504.24658 | U9: =L9/$P9 -> 402.74361 | V9: =M9/$P9 -> 329.16096 | W9: =N9/$P9 -> 271.35936 | X9: =O9/$P9 -> 238.11644 | Y9: =AVERAGE(H9/D9,I9/E9,J9/F9) -> 1.059505 | Z9: =H9/$Y9 -> 711.46434 | AA9: =I9/$Y9 -> 674.27716 | AB9: =J9/$Y9 -> 589.33183 | AC9: =K9/$Y9 -> 509.67198 | AD9: =L9/$Y9 -> 407.0769 | AE9: =M9/$Y9 -> 332.70255 | AF9: =N9/$Y9 -> 274.27903 | AG9: =O9/$Y9 -> 240.67844 | AI9: 281.3 | AJ9: 244.7 | AK9: A16C | AL9: =X9 -> 238.11644

Sheet DRIE etch rates
A1: Wafer | B1: Loops | C1: Photoresist before: | D1: Oxide before: | E1: Total mask before: | F1: Mask after: | G1: Depth before: | H1: Depth after: | I1: Total etched: | J1: Etch rate: | K1: Erosion:
A2: A5 | B2: 500 | C2: ='batch 1 data'!AE7 -> 2 | D2: =('batch 1 data'!F7/1000) -> 3.975 | E2: =C2+D2 -> 5.975 | F2: ='batch 1 data'!AY7/1000 -> 2.2705 | G2: ='batch 1 data'!AL7 -> 6.6818 | H2: ='batch 1 data'!BF7 -> 299.362 | I2: =(H2-F2)-(G2-E2) -> 296.3847 | J2: =I2/B2 -> 0.5927694 | K2: =(D2-F2)/(B2-(C2/0.013)) -> 0.0049241111
A3: A6 | B3: 945 | C3: ='batch 1 data'!AE8 -> 1.72902 | D3: =('batch 1 data'!F8/1000) -> 4.075 | E3: =C3+D3 -> 5.80402 | F3: ='batch 1 data'!AY8/1000 -> 1.43838 | G3: ='batch 1 data'!AL8 -> 6.2322 | H3: ='batch 1 data'!BF8 -> 597.824 | I3: =(H3-F3)-(G3-E3) -> 595.95744 | J3: =I3/B3 -> 0.63064279 | K3: =(D3-F3)/(B3-(C3/0.013)) -> 0.0032470751
A4: A7 | B4: 1045 | C4: ='batch 1 data'!AE9 -> 2.11696 | D4: =('batch 1 data'!F9/1000) -> 4.025 | E4: =C4+D4 -> 6.14196 | F4: ='batch 1 data'!AY9/1000 -> 1.21744 | G4: ='batch 1 data'!AL9 -> 6.5166 | H4: ='batch 1 data'!BF9 -> 639.478 | I4: =(H4-F4)-(G4-E4) -> 637.88592 | J4: =I4/B4 -> 0.61041715 | K4: =(D4-F4)/(B4-(C4/0.013)) -> 0.0031826084
A5: A7b | B5: 200 | C5: ='batch 1 data'!AE10 -> 0 | D5: =F4 -> 1.21744 | E5: =C5+D5 -> 1.21744 | F5: ='batch 1 data'!AY10/1000 -> 0.47546 | G5: =H4 -> 639.478 | H5: ='batch 1 data'!BF10 -> 760 | I5: =(H5-F5)-(G5-E5) -> 121.26398 | J5: =I5/B5 -> 0.6063199 | K5: =(D5-F5)/(B5) -> 0.0037099
A6: A7c | B6: 150 | C6: ='batch 1 data'!AE11 -> 0 | D6: =F5 -> 0.47546 | E6: =C6+D6 -> 0.47546 | F6: ='batch 1 data'!AY11/1000 -> 0.020536 | G6: =H5 -> 760 | H6: 850 | I6: =(H6-F6)-(G6-E6) -> 90.454924 | J6: =I6/B6 -> 0.60303283 | K6: =(D6-F6)/(B6-(C6/0.013)) -> 0.0030328267
A7: A8 | B7: 1295 | C7: ='batch 1 data'!AE12 -> 2.36412 | D7: =('batch 1 data'!F12/1000) -> 4.075 | E7: =C7+D7 -> 6.43912 | F7: ='batch 1 data'!AY12/1000 -> 0.472306 | G7: ='batch 1 data'!AL12 -> 6.6924 | H7: ='batch 1 data'!BF12 -> 800 | I7: =(H7-F7)-(G7-E7) -> 799.27441 | J7: =I7/B7 -> 0.61720032 | K7: =(D7-F7)/(B7-(C7/0.013)) -> 0.0032365013
A9: DOE:
A10: Wafer | B10: Loops | C10: Photoresist before: | D10: Oxide before: | E10: Total mask before: | F10: Mask after: | G10: Depth before: | H10: Depth after: | I10: Total etched: | J10: Etch rate: | K10: Erosion:
A11: A9 | B11: 1295 | C11: =('DOE data'!AL5-('DOE data'!F5/1000))-('DOE data'!$AL$10-('DOE data'!$F$10/1000)) -> 2.2486 | D11: ='DOE data'!F3/1000 -> 4.025 | E11: =C11+D11 -> 6.2736 | F11: ='DOE data'!AY5/1000 -> 0.028995 | G11: ='DOE data'!AL5 -> 6.6924 | H11: ='DOE data'!BD5 -> 726.46667 | I11: =(H11-F11)-(G11-E11) -> 726.01887 | J11: =I11/B11 -> 0.56063233 | K11: =(D11-F11)/(B11-(C11/0.013)) -> 0.0035614041 | M11: A11b | N11: C | O11: S | P11: E
A12: A10 | B12: 1295 | C12: =('DOE data'!AL6-('DOE data'!F6/1000))-('DOE data'!$AL$10-('DOE data'!$F$10/1000)) -> 2.7292 | D12: ='DOE data'!F4/1000 -> 4.075 | E12: =C12+D12 -> 6.8042 | F12: ='DOE data'!AY6/1000 -> 0.524 | G12: ='DOE data'!AL6 -> 7.209 | H12: ='DOE data'!BD6 -> 823.23333 | I12: =(H12-F12)-(G12-E12) -> 822.30453 | J12: =I12/B12 -> 0.6349842 | K12: =(D12-F12)/(B12-(C12/0.013)) -> 0.0032726254 | M12: 500 | N12: 654.8 | O12: 652.9 | P12: 658.9
A13: A11 | B13: 1295 | C13: ='DOE data'!AE7 -> 1.6586 | D13: ='DOE data'!F5/1000 -> 3.975 | E13: =C13+D13 -> 5.6336 | F13: ='DOE data'!AY7/1000 -> 0.1119 | G13: ='DOE data'!AL7 -> 6.4888 | H13: ='DOE data'!BD7 -> 834.4 | I13: =(H13-F13)-(G13-E13) -> 833.4329 | J13: =I13/B13 -> 0.64357753 | K13: =(D13-F13)/(B13-(C13/0.013)) -> 0.0033091049 | M13: 200 | N13: 588.8 | O13: 591.3 | P13: 592.9
A14: A12 | B14: 1295 | C14: ='DOE data'!AE8 -> 1.88182 | D14: ='DOE data'!F6/1000 -> 4.011 | E14: =C14+D14 -> 5.89282 | G14: ='DOE data'!AL8 -> 6.3816 | M14: 100 | N14: 523.2 | O14: 527.8 | P14: 525.5
A15: A13 | B15: 1295 | C15: =('DOE data'!AL9-('DOE data'!F9/1000))-('DOE data'!$AL$10-('DOE data'!$F$10/1000)) -> 2.5596 | D15: ='DOE data'!F7/1000 -> 4.091 | E15: =C15+D15 -> 6.6506 | F15: ='DOE data'!AY9/1000 -> 0.42772 | G15: ='DOE data'!AL9 -> 7.1194 | H15: ='DOE data'!BD9 -> 822.13333 | I15: =(H15-F15)-(G15-E15) -> 821.23681 | J15: =I15/B15 -> 0.6341597 | K15: =(D15-F15)/(B15-(C15/0.013)) -> 0.0033359934
A16: A14 | B16: 1295 | C16: =('DOE data'!AL10-('DOE data'!F10/1000))-('DOE data'!$AL$10-('DOE data'!$F$10/1000)) -> 0 | D16: ='DOE data'!F8/1000 -> 4.081 | E16: =C16+D16 -> 4.081 | G16: ='DOE data'!AL10 -> 4.4538 | M16: A11c | N16: C | O16: S | P16: E
A17: A15 | B17: 1295 | C17: ='DOE data'!AE11 -> 1.69495 | D17: ='DOE data'!F9/1000 -> 4.091 | E17: =C17+D17 -> 5.78595 | G17: ='DOE data'!AL11 -> 6.3468 | M17: 500 | N17: 829.8 | O17: 831.2 | P17: 842.2
A18: A16 | B18: 1295 | C18: =('DOE data'!AL12-('DOE data'!F12/1000))-('DOE data'!$AL$10-('DOE data'!$F$10/1000)) -> 2.6586 | D18: ='DOE data'!F10/1000 -> 3.985 | E18: =C18+D18 -> 6.6436 | G18: ='DOE data'!AL12 -> 7.1764 | M18: 200 | N18: 744 | O18: 746.3 | P18: 751.4
M19: 100 | N19: 656.4 | O19: 656 | P19: 659.7

Sheet Process flow
B1: High aspect ratio process development project
A2: step | B2: Tool | C2: Recipe | D2: Notes | E2: Purpose
A3: 0 Ash | B3: YES asher | C3: Recipe 4 Descum | D3: Ash immediately prior to deposition | E3: Wafer clean
A4: 1. Oxide | B4: PECVD2 | C4: Oxide: USER_SiO2_350_4u | D4: Oxide: 426 nm/min, time = 9.4 min | E4: Silicon oxide will be the hardmask for the DRIE etching
A5: 2 Filmetrics | B5: Filmetrics | C5: SiO2 on Si | D5: Si reference wafer, edit expected thickness to 4000 nm | E5: confirm SiO2 thickness
A6: 3. Ash | B6: YES asher | C6: Recipe 4 Descum | D6: Ash immediately prior to coating | E6: Improve resist adhesion
A7: 4 COAT | B7: Rite Track (coater side) | C7: 10XTD2 | D7: AZ10XT, 7 um | E7: HMDS, coat, bake to deposit photoresist
A8: 4.1 EBR | B8: Rite Track (coater side) | C8: TOPEBR20 | E8: remove edge bead for ICP-F etcher (SiO2 etching)
A9: 5. REHYDRATE | C9: 30 min | E9: Important!!! Don't skip this step otherwise photoresist will crack post develop
A10: 6. FILMETRICS | B10: Filmetrics | C10: MFF AZ10xT on SiO2 | D10: Si reference wafer, edit expected thickness to 7 um over 4 um | E10: measure resist thickness
A11: 7. EXPOSE | B11: ABM | C11: 84s total, split into two 42 second intervals with at least 30s inbetween exposure. | D11: Use WNF Uniformity Mask | E11: Expose test pattern into resist
A12: 8. DEVELOP | B12: Rite Track (developer Track) | C12: DEV6 | E12: Dissolve exposed regions of resist in developer to transfer mask pattern into resist
A13: 9. INSPECT | B13: NIKON | D13: Check for completed develop and flaws (NOTE: features with sizes less than 3um may not resolve.) | E13: Visually confirm exposure and development of resist
A14: 10. DESCUM | B14: YES asher | C14: Recipe 4 Descum | D14: Recipe 4 | E14: cleans remnants of exposed-yet-undeveloped resist via a low-power oxygen plasma
A15: 11. DEKTAK | B15: Dektak | C15: Standard scan, range = 65.5 um, hills and valleys, length = 500 um, resolution = 0.1 | D15: Measure 500 um trench 270 degrees for S,E,C (intuitive coordinates) 90 degrees for N and W (inverse coordinates) | E15: Measure resist thickness for direct comparison to post etching measurement. NOTE: This tool has a minimum trench width capability and typically is used to measure only the 500um or 200um wide trench depth. | I15: measure south, east, center at 270 degrees (intuitive coordinates), then flip to 90 degrees and measure north and west (inverse)
A16: 11.1 SEM* | B16: SEM | D16: Sacrifice 1 wafer, cut across features, Do cross-section SEM with 45 degree angle stage, coat gold (Au/Pd recipe 30 sec) to minimize charging effect | E16: verify side wall profile of resist --> looks good with current setup✅
A17: 12. Etch oxide hardmask | B17: ICP-F | C17: QT SiO2 Etch-C4F8/O2 20C 5mT, 10.5 min | D17: To avoid reticulation, rest for one minute in chamber after 5m15s | E17: Removal of the SiO2 layer in the exposed areas
A18: 13. Nanospec | B18: Nanospec | C18: WNF folder: Grace -AZ10xT onSiO2 on Si | D18: Edit recipe --> 2 um on 4 um, measure unetched area in five different spots | E18: Measure remaining photoresist thickness
A19: 14. Dektak | B19: Dektak | C19: Standard scan, range = 65.5 um, hills and valleys, length = 500 um, resolution = 0.1 | D19: Measure 500 um trench 270 degrees for S,E,C (intuitive coordinates) 90 degrees for W (inverse coordinates), 180 degrees for major flat | I19: due to ICP clamp, should rotate 0 degrees for major flat measurement and find clean feature
A20: 14.1 SEM * | B20: SEM | D20: Sacrifice 1 wafer, cut across features, Do cross-section SEM with 45 degree angle stage, coat gold (Au/Pd recipe 30 sec) to minimize charging effect | E20: verify side wall profile of resist, SiO2 fully etched in trenches --> looks good with current setup✅
A21: 15. SPTS-DRIE DOE etch | B21: SPTS-DRIE | C21: See SPTS-DRIE tab | D21: Target: 500 um
A22: 16. Nanospec | B22: Nanospec | C22: MFF SiO2 on Si | D22: Measure unetched area | E22: SiO2 thickness
A23: 17. Dektak | B23: Dektak | C23: Standard scan, range = 1 mm, valleys, length = 600 um, resolution = 0.1 | D23: Measure 500 um trench | E23: SiO2 + trench depth
A24: 18. SEM | B24: SEM | D24: Sacrifice 1 wafer, cut across features, Do cross-section SEM with 45 degree angle stage, coat gold (Au/Pd recipe 30 sec) to minimize charging effect | E24: Verify etch depth, check side wall profile etc.
A27: For second batch:
A28: 17. Keyence | B28: Keyence | D28: Measure 500 um, 200 um, and 100 um trench of C, S, E features | E28: SiO2 + trench depth

Sheet Drop gauge
B1: C | C1: E | D1: S | E1: Mean | F1: U
A2: Assumption before: | B2: 1025 | C2: 1025 | D2: 1025 | E2: =AVERAGE(B2:D2) -> 1025 | F2: =(MAX(B2:D2)-MIN(B2:D2))/(2*E2) -> 0
A3: A14 before: | B3: 1026.9 | C3: 1022.7 | D3: 1019.1 | E3: =AVERAGE(B3:D3) -> 1022.9 | F3: =(MAX(B3:D3)-MIN(B3:D3))/(2*E3) -> 0.0038126894
A5: A9 after: | B5: 1001.1 | C5: 1006.6 | D5: 1019.9 | E5: =AVERAGE(B5:D5) -> 1009.2 | F5: =(MAX(B5:D5)-MIN(B5:D5))/(2*E5) -> 0.0093143084
A6: A10 after: | B6: 1020.2 | C6: 1040.6 | D6: 1012.7 | E6: =AVERAGE(B6:D6) -> 1024.5 | F6: =(MAX(B6:D6)-MIN(B6:D6))/(2*E6) -> 0.013616398
A7: A11 after: | B7: 1034.5 | C7: 1035.08 | D7: 1019 | E7: =AVERAGE(B7:D7) -> 1029.5267 | F7: =(MAX(B7:D7)-MIN(B7:D7))/(2*E7) -> 0.007809414
A8: A12 after: | B8: 998.4 | C8: 1024.4 | D8: 1004.1 | E8: =AVERAGE(B8:D8) -> 1008.9667 | F8: =(MAX(B8:D8)-MIN(B8:D8))/(2*E8) -> 0.012884469
A9: A13 after: | B9: 1022.1 | C9: 1025.2 | D9: 1017.1 | E9: =AVERAGE(B9:D9) -> 1021.4667 | F9: =(MAX(B9:D9)-MIN(B9:D9))/(2*E9) -> 0.0039648871
A10: A14 after: | B10: 929.82 | C10: 921.98 | D10: 918.9 | E10: =AVERAGE(B10:D10) -> 923.56667 | F10: =(MAX(B10:D10)-MIN(B10:D10))/(2*E10) -> 0.0059118634
A11: A15 after: | B11: 963.8 | C11: 975.63 | D11: 971.38 | E11: =AVERAGE(B11:D11) -> 970.27 | F11: =(MAX(B11:D11)-MIN(B11:D11))/(2*E11) -> 0.0060962413
A12: A16 after: | B12: 1022.5 | C12: 985.8 | D12: 925.7 | E12: =AVERAGE(B12:D12) -> 978 | F12: =(MAX(B12:D12)-MIN(B12:D12))/(2*E12) -> 0.049488753
A14: A9 etched: | B14: =$B$2-B5 -> 23.9 | C14: =$B$2-C5 -> 18.4 | D14: =$B$2-D5 -> 5.1 | E14: =AVERAGE(B14:D14) -> 15.8 | F14: =(MAX(B14:D14)-MIN(B14:D14))/(2*E14) -> 0.59493671
A15: A10 etched: | B15: =$B$2-B6 -> 4.8 | C15: =$B$2-C6 -> -15.6 | D15: =$B$2-D6 -> 12.3 | E15: =AVERAGE(B15:D15) -> 0.5 | F15: =(MAX(B15:D15)-MIN(B15:D15))/(2*E15) -> 27.9
A16: A11 etched: | B16: =$B$2-B7 -> -9.5 | C16: =$B$2-C7 -> -10.08 | D16: =$B$2-D7 -> 6 | E16: =AVERAGE(B16:D16) -> -4.5266667 | F16: =(MAX(B16:D16)-MIN(B16:D16))/(2*E16) -> -1.7761414
A17: A12 etched: | B17: =$B$2-B8 -> 26.6 | C17: =$B$2-C8 -> 0.6 | D17: =$B$2-D8 -> 20.9 | E17: =AVERAGE(B17:D17) -> 16.033333 | F17: =(MAX(B17:D17)-MIN(B17:D17))/(2*E17) -> 0.81081081
A18: A13 etched: | B18: =$B$2-B9 -> 2.9 | C18: =$B$2-C9 -> -0.2 | D18: =$B$2-D9 -> 7.9 | E18: =AVERAGE(B18:D18) -> 3.5333333 | F18: =(MAX(B18:D18)-MIN(B18:D18))/(2*E18) -> 1.1462264
A19: A14 etched: | B19: =B3-B10 -> 97.08 | C19: =C3-C10 -> 100.72 | D19: =D3-D10 -> 100.2 | E19: =AVERAGE(B19:D19) -> 99.333333 | F19: =(MAX(B19:D19)-MIN(B19:D19))/(2*E19) -> 0.018322148
A20: A15 etched: | B20: =$B$2-B11 -> 61.2 | C20: =$B$2-C11 -> 49.37 | D20: =$B$2-D11 -> 53.62 | E20: =AVERAGE(B20:D20) -> 54.73 | F20: =(MAX(B20:D20)-MIN(B20:D20))/(2*E20) -> 0.10807601
A21: A16 etched: | B21: =$B$2-B12 -> 2.5 | C21: =$B$2-C12 -> 39.2 | D21: =$B$2-D12 -> 99.3 | E21: =AVERAGE(B21:D21) -> 47 | F21: =(MAX(B21:D21)-MIN(B21:D21))/(2*E21) -> 1.0297872

Sheet batch 1 data
A1: Wafer | D1: 2 Filmetrics | I1: 6 Filmetrics | N1: 11 DEKTAK | U1: 12 ETCH | Y1: 13 NANOSPEC | AG1: 14 DEKTAK | AN1: 15 ETCH | AS1: 16 NANOSPEC | BA1: 17 DEKTAK | BH1: 18 SEM | BM1: Etch Rate | BN1: Erosion | BO1: Selectivity | BP1: Aspect Ratio
B2: Completed | C2: Next Step | D2: Min | E2: Max | F2: Mean | G2: Std. Dev. | H2: Unif. [%] | I2: Min | J2: Max | K2: Mean | L2: Std. Dev. | M2: Unif. [%] | N2: C | O2: N (major flat) | P2: E | Q2: S | R2: W | S2: Mean | T2: U | U2: Tool/Operator | V2: Recipe | W2: Etch time | X2: Date | Y2: Recipe | Z2: C | AA2: N (major flat) | AB2: E | AC2: S | AD2: W | AE2: Mean | AF2: U | AG2: C | AH2: N (major flat) | AI2: E | AJ2: S | AK2: W | AL2: Mean | AM2: U | AN2: Tool/Operator | AO2: Recipe | AP2: He (sccm@torr) or bias/CL/CT/APC | AQ2: Loops or min | AR2: Date | AS2: Recipe | AT2: C | AU2: N (major flat) | AV2: E | AW2: S | AX2: W | AY2: Mean | AZ2: U | BA2: C | BB2: N (major flat) | BC2: E | BD2: S | BE2: W | BF2: Mean | BG2: U | BH2: Step: | BI2: 500um depth | BJ2: 5um depth | BK2: 5um width | BL2: Comments | BM2: um/loop | BN2: um/loop (SiO2) | BO2: (SiO2/Si) | BP2: (in 5um trench)
A3: A1 | B3: 11.1 SEM* | D3: 4000 | E3: 4050 | F3: =AVERAGE(D3,E3) -> 4025 | I3: 7 | J3: 7.3 | K3: =AVERAGE(I3,J3) -> 7.15 | N3: 7.071 | O3: 7.214 | P3: 7.183 | Q3: 7.194 | R3: 7.208 | S3: =AVERAGE(N3:R3) -> 7.174 | T3: =(MAX(N3:R3)-MIN(N3:R3))/(2*S3) -> 0.0099665459 | BH3: 11.1 SEM* | BL3: everything looks good
A4: A2 | B4: 14.1 SEM* | D4: 4050 | E4: 4100 | F4: =AVERAGE(D4,E4) -> 4075 | I4: 7 | J4: 7.4 | K4: =AVERAGE(I4,J4) -> 7.2 | N4: 7.126 | O4: 7.389 | P4: 7.249 | Q4: 7.253 | R4: 7.213 | S4: =AVERAGE(N4:R4) -> 7.246 | T4: =(MAX(N4:R4)-MIN(N4:R4))/(2*S4) -> 0.018147944 | U4: ICP-F/MD | V4: QT SiO2 Etch-C4F8/O2 | W4: 2*7.5 min | X4: 45646 | AG4: 5.495 | AH4: 5.834 | AI4: 5.565 | AJ4: 5.676 | AK4: 5.8 | AL4: =AVERAGE(AG4:AK4) -> 5.674 | AM4: =(MAX(AG4:AK4)-MIN(AG4:AK4))/(2*AL4) -> 0.029873105 | BH4: 14.1 SEM* | BL4: probably overetched
A5: A3 | B5: 14.1 SEM* | D5: 4050 | E5: 4100 | F5: =AVERAGE(D5,E5) -> 4075 | I5: 7.1 | J5: 7.4 | K5: =AVERAGE(I5,J5) -> 7.25 | N5: 7.053 | O5: 7.199 | P5: 7.056 | Q5: 7.184 | R5: 7.223 | S5: =AVERAGE(N5:R5) -> 7.143 | T5: =(MAX(N5:R5)-MIN(N5:R5))/(2*S5) -> 0.011899762 | U5: ICP-F/MD | V5: QT SiO2 Etch-C4F8/O2 | W5: 2*6 min | X5: 45646 | AG5: 6.526 | AH5: 6.521 | AI5: 6.511 | AJ5: 6.595 | AK5: 6.528 | AL5: =AVERAGE(AG5:AK5) -> 6.5362 | AM5: =(MAX(AG5:AK5)-MIN(AG5:AK5))/(2*AL5) -> 0.006425752 | BH5: 14.1 SEM* | BL5: 20% overetched in 5um feature
A6: A4 | B6: 14.1 SEM* | D6: 4050 | E6: 4100 | F6: =AVERAGE(D6,E6) -> 4075 | I6: 7 | J6: 7.3 | K6: =AVERAGE(I6,J6) -> 7.15 | N6: 6.999 | O6: 7.245 | P6: 7.141 | Q6: 7.208 | R6: 7.194 | S6: =AVERAGE(N6:R6) -> 7.1574 | T6: =(MAX(N6:R6)-MIN(N6:R6))/(2*S6) -> 0.017185011 | U6: ICP-F/MD | V6: QT SiO2 Etch-C4F8/O2 | W6: 2*5.25 min | X6: 45659 | BH6: 14.1 SEM* | BL6: 5-15% overetched
A7: A5 | B7: 18. SEM | D7: 3950 | E7: 4000 | F7: =AVERAGE(D7,E7) -> 3975 | I7: 6.9 | J7: 7.2 | K7: =AVERAGE(I7,J7) -> 7.05 | N7: 6.997 | O7: 7.206 | P7: 7.195 | Q7: 7.255 | R7: 7.335 | S7: =AVERAGE(N7:R7) -> 7.1976 | T7: =(MAX(N7:R7)-MIN(N7:R7))/(2*S7) -> 0.023480049 | U7: ICP-F/MD | V7: QT SiO2 Etch-C4F8/O2 | W7: 2*5.25 min | X7: 45659 | AE7: 2 | AG7: 6.582 | AH7: 6.721 | AI7: 6.711 | AJ7: 6.704 | AK7: 6.691 | AL7: =AVERAGE(AG7:AK7) -> 6.6818 | AM7: =(MAX(AG7:AK7)-MIN(AG7:AK7))/(2*AL7) -> 0.010401389 | AN7: SPTS-DRIE/MD | AO7: MM_Deep_Standard_-3 | AP7: 14.5 sccm | AQ7: 500 | AR7: 45670 | AS7: MFF SiO2 on Si | AT7: 2270.5 | AY7: =AVERAGE(AT7:AX7) -> 2270.5 | AZ7: =(MAX(AT7:AX7)-MIN(AT7:AX7))/(2*AY7) -> 0 | BA7: 300.12 | BB7: 297.62 | BC7: 301.43 | BD7: 298.41 | BE7: 299.23 | BF7: =AVERAGE(BA7:BE7) -> 299.362 | BG7: =(MAX(BA7:BE7)-MIN(BA7:BE7))/(2*BF7) -> 0.0063635331 | BH7: 18. SEM | BI7: 303.8 | BJ7: 131.4 | BK7: 5 | BL7: pillars toppled, difficulty etching smaller trenches | BM7: =(BF7-AY7/1000)/AQ7 -> 0.594183 | BN7: =((F7-AY7)/1000)/(AQ7-(AE7/0.013)) -> 0.0049241111 | BO7: =BM7/BN7 -> 120.66807 | BP7: =(BE7/BI7)*BJ7/BK7 -> 25.884675
A8: A6 | B8: 18. SEM | D8: 4050 | E8: 4100 | F8: =AVERAGE(D8,E8) -> 4075 | I8: 6.9 | J8: 7.5 | K8: =AVERAGE(I8,J8) -> 7.2 | N8: 7.066 | O8: 7.165 | P8: 7.146 | Q8: 7.172 | R8: 7.183 | S8: =AVERAGE(N8:R8) -> 7.1464 | T8: =(MAX(N8:R8)-MIN(N8:R8))/(2*S8) -> 0.0081859398 | U8: ICP-F/MD | V8: QT SiO2 Etch-C4F8/O2 | W8: 2*5.25 min | X8: 45677 | Y8: Grace -AZ10xT onSiO2 on Si | Z8: 1.5332 | AA8: 1.7725 | AB8: 1.6936 | AC8: 1.853 | AD8: 1.7928 | AE8: =AVERAGE(Z8:AD8) -> 1.72902 | AF8: =(MAX(Z8:AD8)-MIN(Z8:AD8))/(2*AE8) -> 0.092480133 | AG8: 6.166 | AH8: 6.152 | AI8: 6.205 | AJ8: 6.39 | AK8: 6.248 | AL8: =AVERAGE(AG8:AK8) -> 6.2322 | AM8: =(MAX(AG8:AK8)-MIN(AG8:AK8))/(2*AL8) -> 0.019094381 | AN8: SPTS-DRIE/MD | AO8: MM_Deep_3X_-3 | AP8: 14.2 sccm | AQ8: 945 | AR8: 45686 | AS8: MFF SiO2 on Si | AT8: 1273.1 | AU8: 1609.7 | AV8: 1394.4 | AW8: 1339.9 | AX8: 1574.8 | AY8: =AVERAGE(AT8:AX8) -> 1438.38 | AZ8: =(MAX(AT8:AX8)-MIN(AT8:AX8))/(2*AY8) -> 0.11700663 | BA8: 600.03 | BB8: 595 | BC8: 600.27 | BD8: 594.75 | BE8: 599.07 | BF8: =AVERAGE(BA8:BE8) -> 597.824 | BG8: =(MAX(BA8:BE8)-MIN(BA8:BE8))/(2*BF8) -> 0.0046167434 | BH8: 18. SEM | BI8: 613.1 | BJ8: 234.6 | BK8: 5 | BL8: 500 um trench has angled sidewalls | BM8: ='DRIE etch rates'!J3 -> 0.63064279 | BN8: =((F8-AY8)/1000)/(AQ8-(AE8/0.013)) -> 0.0032470751 | BO8: =BM8/BN8 -> 194.21873 | BP8: =(BE8/BI8)*BJ8/BK8 -> 45.846297
A9: A7 | D9: 4000 | E9: 4050 | F9: =AVERAGE(D9,E9) -> 4025 | I9: 7.1 | J9: 7.4 | K9: =AVERAGE(I9,J9) -> 7.25 | N9: 7.044 | O9: 7.185 | P9: 7.109 | Q9: 7.075 | R9: 7.115 | S9: =AVERAGE(N9:R9) -> 7.1056 | T9: =(MAX(N9:R9)-MIN(N9:R9))/(2*S9) -> 0.0099217519 | U9: ICP-F/MD | V9: QT SiO2 Etch-C4F8/O2 | W9: 2*5.25 min | X9: 45677 | Y9: Grace -AZ10xT onSiO2 on Si | Z9: 1.8881 | AA9: 2.1422 | AB9: 2.1121 | AC9: 2.2328 | AD9: 2.2096 | AE9: =AVERAGE(Z9:AD9) -> 2.11696 | AF9: =(MAX(Z9:AD9)-MIN(Z9:AD9))/(2*AE9) -> 0.081413914 | AG9: 6.44 | AH9: 6.415 | AI9: 6.532 | AJ9: 6.638 | AK9: 6.558 | AL9: =AVERAGE(AG9:AK9) -> 6.5166 | AM9: =(MAX(AG9:AK9)-MIN(AG9:AK9))/(2*AL9) -> 0.017110149 | AN9: SPTS-DRIE/MD | AO9: MM_Deep_3X_-3 | AP9: 17.0 sccm | AQ9: 1045 | AR9: 45709 | AS9: MFF SiO2 on Si | AT9: 1144.4 | AU9: 1152.1 | AV9: 1216.1 | AW9: 1314.5 | AX9: 1260.1 | AY9: =AVERAGE(AT9:AX9) -> 1217.44 | AZ9: =(MAX(AT9:AX9)-MIN(AT9:AX9))/(2*AY9) -> 0.069859706 | BA9: 642.49 | BB9: 637.62 | BC9: 645.63 | BD9: 632.55 | BE9: 639.1 | BF9: =AVERAGE(BA9:BE9) -> 639.478 | BG9: =(MAX(BA9:BE9)-MIN(BA9:BE9))/(2*BF9) -> 0.010227091 | BM9: =(BF9-AY9/1000)/AQ9 -> 0.61077566 | BN9: =((F9-AY9)/1000)/(AQ9-(AE9/0.013)) -> 0.0031826084 | BO9: =BM9/BN9 -> 191.9104
A10: A7b | AN10: SPTS-DRIE/MD | AO10: MM_Deep_3X_-3 | AP10: 17.0 sccm | AQ10: 200 | AR10: 45714 | AS10: MFF SiO2 on Si | AT10: 388.89 | AU10: 404.65 | AV10: 494.43 | AW10: 594.53 | AX10: 494.8 | AY10: =AVERAGE(AT10:AX10) -> 475.46 | AZ10: =(MAX(AT10:AX10)-MIN(AT10:AX10))/(2*AY10) -> 0.21625373 | BA10: From Keyence, depth was between 750-800 um | BF10: 760
A11: A7c | B11: 18. SEM | AN11: SPTS-DRIE/MD | AO11: MM_Deep_3X_-3 | AP11: 17.0 sccm | AQ11: 150 | AR11: 45714 | AS11: MFF SiO2 on Si | AT11: 0 | AU11: 0 | AV11: 0 | AW11: 51.01 | AX11: 51.67 | AY11: =AVERAGE(AT11:AX11) -> 20.536 | AZ11: =(MAX(AT11:AX11)-MIN(AT11:AX11))/(2*AY11) -> 1.2580347 | BA11: From Keyence, depth was about 850 um | BF11: 850 | BH11: 18. SEM | BL11: SWW feature
A12: A8 | B12: 18. SEM | D12: 4050 | E12: 4100 | F12: =AVERAGE(D12,E12) -> 4075 | I12: 7.1 | J12: 7.6 | K12: =AVERAGE(I12,J12) -> 7.35 | N12: 7.108 | O12: 7.171 | P12: 7.148 | Q12: 7.175 | R12: 7.145 | S12: =AVERAGE(N12:R12) -> 7.1494 | T12: =(MAX(N12:R12)-MIN(N12:R12))/(2*S12) -> 0.0046857079 | U12: ICP-F/MD | V12: QT SiO2 Etch-C4F8/O2 | W12: 2*5.25 min | X12: 45677 | Y12: Grace -AZ10xT onSiO2 on Si | Z12: 2.1839 | AA12: 2.2987 | AB12: 2.4897 | AC12: 2.4646 | AD12: 2.3837 | AE12: =AVERAGE(Z12:AD12) -> 2.36412 | AF12: =(MAX(Z12:AD12)-MIN(Z12:AD12))/(2*AE12) -> 0.064675228 | AG12: 6.674 | AH12: 6.607 | AI12: 6.664 | AJ12: 6.847 | AK12: 6.67 | AL12: =AVERAGE(AG12:AK12) -> 6.6924 | AM12: =(MAX(AG12:AK12)-MIN(AG12:AK12))/(2*AL12) -> 0.017930787 | AN12: SPTS-DRIE/MD | AO12: MM_Deep_3XwC_-3 | AP12: 16.5 sccm | AQ12: 1295 | AR12: 45716 | AS12: MFF SiO2 on Si | AT12: 383.81 | AU12: 369.38 | AV12: 487.03 | AW12: 609.43 | AX12: 511.88 | AY12: =AVERAGE(AT12:AX12) -> 472.306 | AZ12: =(MAX(AT12:AX12)-MIN(AT12:AX12))/(2*AY12) -> 0.2541255 | BA12: From Keyence, depth was about 800 um | BF12: 800 | BH12: 18. SEM

Sheet DOE data
A1: Wafer | D1: 2 Filmetrics | I1: 6 Filmetrics | N1: 11 DEKTAK | U1: 12 ETCH | Y1: 13 NANOSPEC | AG1: 14 DEKTAK | AN1: 15 ETCH | AS1: 16 NANOSPEC | BA1: 17 Keyence (500 um) | BF1: 17 Keyence (200 um) | BK1: 17 Keyence (100 um) | BP1: 18 SEM | BU1: Etch Rate | BV1: Erosion | BW1: Selectivity | BX1: Aspect Ratio
B2: Completed | C2: Next Step | D2: Min | E2: Max | F2: Mean | G2: Std. Dev. | H2: Unif. [%] | I2: Min | J2: Max | K2: Mean | L2: Std. Dev. | M2: Unif. [%] | N2: C | O2: N (major flat) | P2: E | Q2: S | R2: W | S2: Mean | T2: U | U2: Tool/Operator | V2: Recipe | W2: Etch time | X2: Date | Y2: Recipe | Z2: C | AA2: N (major flat) | AB2: E | AC2: S | AD2: W | AE2: Mean | AF2: U | AG2: C | AH2: N (major flat) | AI2: E | AJ2: S | AK2: W | AL2: Mean | AM2: U | AN2: Tool/Operator | AO2: Recipe | AP2: He (sccm@torr) or bias/CL/CT/APC | AQ2: Loops or min | AR2: Date | AS2: Recipe | AT2: C | AU2: N (major flat) | AV2: E | AW2: S | AX2: W | AY2: Mean | AZ2: U | BA2: C | BB2: S | BC2: E | BD2: Mean | BE2: U | BF2: C | BG2: S | BH2: E | BI2: Mean | BJ2: U | BK2: C | BL2: S | BM2: E | BN2: Mean | BO2: U | BP2: 500um depth | BQ2: 200um depth | BR2: 100um depth | BS2: 5um depth (200+) | BT2: Comments | BU2: um/loop | BV2: um/loop (SiO2) | BW2: (SiO2/Si) | BX2: (in 5um trench)
A3: A7 | B3: 18. SEM | D3: 4000 | E3: 4050 | F3: =AVERAGE(D3,E3) -> 4025 | I3: 7.1 | J3: 7.4 | K3: =AVERAGE(I3,J3) -> 7.25 | N3: 7.044 | O3: 7.185 | P3: 7.109 | Q3: 7.075 | R3: 7.115 | S3: =AVERAGE(N3:R3) -> 7.1056 | T3: =(MAX(N3:R3)-MIN(N3:R3))/(2*S3) -> 0.0099217519 | U3: ICP-F/MD | V3: QT SiO2 Etch-C4F8/O2 | W3: 2*5.25 min | X3: 45677 | Y3: Grace -AZ10xT onSiO2 on Si | Z3: 1.8881 | AA3: 2.1422 | AB3: 2.1121 | AC3: 2.2328 | AD3: 2.2096 | AE3: =AVERAGE(Z3:AD3) -> 2.11696 | AF3: =(MAX(Z3:AD3)-MIN(Z3:AD3))/(2*AE3) -> 0.081413914 | AG3: 6.44 | AH3: 6.415 | AI3: 6.532 | AJ3: 6.638 | AK3: 6.558 | AL3: =AVERAGE(AG3:AK3) -> 6.5166 | AM3: =(MAX(AG3:AK3)-MIN(AG3:AK3))/(2*AL3) -> 0.017110149 | AN3: SPTS-DRIE/MD | AO3: MM_Deep_3X_-3 | AP3: 17.0 sccm | AQ3: 150 | AR3: 45714 | AS3: MFF SiO2 on Si | AT3: 0 | AU3: 0 | AV3: 0 | AW3: 51.01 | AX3: 51.67 | AY3: =AVERAGE(AT3:AX3) -> 20.536 | AZ3: =(MAX(AT3:AX3)-MIN(AT3:AX3))/(2*AY3) -> 1.2580347 | BB3: 845 | BD3: =AVERAGE(BA3:BC3) -> 845 | BE3: =(MAX(BA3:BC3)-MIN(BA3:BC3))/(2*BD3) -> 0 | BG3: 746 | BI3: =AVERAGE(BF3:BH3) -> 746 | BJ3: =(MAX(BA3:BC3)-MIN(BA3:BC3))/(2*BD3) -> 0 | BL3: 655 | BN3: =AVERAGE(BK3:BM3) -> 655 | BO3: =(MAX(BF3:BH3)-MIN(BF3:BH3))/(2*BI3) -> 0 | BP3: 860.8 | BQ3: 772.2 | BR3: 683.5 | BS3: 304.9 | BT3: SWW feature
A4: A8 | B4: 18. SEM | D4: 4050 | E4: 4100 | F4: =AVERAGE(D4,E4) -> 4075 | I4: 7.1 | J4: 7.6 | K4: =AVERAGE(I4,J4) -> 7.35 | N4: 7.108 | O4: 7.171 | P4: 7.148 | Q4: 7.175 | R4: 7.145 | S4: =AVERAGE(N4:R4) -> 7.1494 | T4: =(MAX(N4:R4)-MIN(N4:R4))/(2*S4) -> 0.0046857079 | U4: ICP-F/MD | V4: QT SiO2 Etch-C4F8/O2 | W4: 2*5.25 min | X4: 45677 | Y4: Grace -AZ10xT onSiO2 on Si | Z4: 2.1839 | AA4: 2.2987 | AB4: 2.4897 | AC4: 2.4646 | AD4: 2.3837 | AE4: =AVERAGE(Z4:AD4) -> 2.36412 | AF4: =(MAX(Z4:AD4)-MIN(Z4:AD4))/(2*AE4) -> 0.064675228 | AG4: 6.674 | AH4: 6.607 | AI4: 6.664 | AJ4: 6.847 | AK4: 6.67 | AL4: =AVERAGE(AG4:AK4) -> 6.6924 | AM4: =(MAX(AG4:AK4)-MIN(AG4:AK4))/(2*AL4) -> 0.017930787 | AN4: SPTS-DRIE/MD | AO4: MM_Deep_3XwC_-3 | AP4: 16.5 sccm | AQ4: 1295 | AR4: 45716 | AS4: MFF SiO2 on Si | AT4: 383.81 | AU4: 369.38 | AV4: 487.03 | AW4: 609.43 | AX4: 511.88 | AY4: =AVERAGE(AT4:AX4) -> 472.306 | AZ4: =(MAX(AT4:AX4)-MIN(AT4:AX4))/(2*AY4) -> 0.2541255 | BA4: 804 | BB4: 797.5 | BC4: 804.2 | BD4: =AVERAGE(BA4:BC4) -> 801.9 | BE4: =(MAX(BA4:BC4)-MIN(BA4:BC4))/(2*BD4) -> 0.0041775783 | BF4: 711.3 | BG4: 708.6 | BH4: 713.1 | BI4: =AVERAGE(BF4:BH4) -> 711 | BJ4: =(MAX(BA4:BC4)-MIN(BA4:BC4))/(2*BD4) -> 0.0041775783 | BK4: 621.6 | BL4: 624.4 | BM4: 625 | BN4: =AVERAGE(BK4:BM4) -> 623.66667 | BO4: =(MAX(BF4:BH4)-MIN(BF4:BH4))/(2*BI4) -> 0.003164557 | BP4: 820.3 | BQ4: 744.9 | BR4: 661.5 | BS4: 292.5 | BT4: C feature
A5: A9 | B5: 18. SEM | D5: 3928 | E5: 4074 | F5: 3975 | G5: 44.17 | H5: 1.8 | I5: 6.31 | J5: 6.769 | K5: 6.598 | L5: 0.08204 | M5: 3.5 | N5: 6.71 | O5: 6.59 | P5: 6.65 | Q5: 6.96 | R5: 6.6 | S5: =AVERAGE(N5:R5) -> 6.702 | T5: =(MAX(N5:R5)-MIN(N5:R5))/(2*S5) -> 0.0276037 | U5: ICP-F/MD | V5: QT SiO2 Etch-C4F8/O2 | W5: 2*5.25 min | X5: 45691 | Y5: Grace -AZ10xT onSiO2 on Si | AG5: 6.879 | AH5: 6.559 | AI5: 6.661 | AJ5: 6.732 | AK5: 6.631 | AL5: =AVERAGE(AG5:AK5) -> 6.6924 | AM5: =(MAX(AG5:AK5)-MIN(AG5:AK5))/(2*AL5) -> 0.023907716 | AN5: SPTS-DRIE/MD | AO5: MD_DOE3_3x_-3 | AP5: 17.1 sccm | AQ5: 1295 | AR5: 45726 | AS5: MFF SiO2 on Si | AT5: 37.26 | AU5: 25.55 | AV5: 26.75 | AX5: 26.42 | AY5: =AVERAGE(AT5:AX5) -> 28.995 | AZ5: =(MAX(AT5:AX5)-MIN(AT5:AX5))/(2*AY5) -> 0.20193137 | BA5: 713.8 | BB5: 741.9 | BC5: 723.7 | BD5: =AVERAGE(BA5:BC5) -> 726.46667 | BE5: =(MAX(BA5:BC5)-MIN(BA5:BC5))/(2*BD5) -> 0.019340185 | BF5: 637.3 | BG5: 688.1 | BH5: 646.2 | BI5: =AVERAGE(BF5:BH5) -> 657.2 | BJ5: =(MAX(BA5:BC5)-MIN(BA5:BC5))/(2*BD5) -> 0.019340185 | BK5: 551.5 | BL5: 579.1 | BM5: 561.2 | BN5: =AVERAGE(BK5:BM5) -> 563.93333 | BO5: =(MAX(BF5:BH5)-MIN(BF5:BH5))/(2*BI5) -> 0.038648813 | BP5: 806.3 | BT5: S feature
A6: A10 | B6: 18. SEM | D6: 3969 | E6: 4102 | F6: 4011 | G6: 40.04 | H6: 1.7 | I6: 6.906 | J6: 7.335 | K6: 7.171 | L6: 0.0998 | M6: 3 | N6: 7.08 | O6: 7.2 | P6: 7.19 | Q6: 7.22 | R6: 7.21 | S6: =AVERAGE(N6:R6) -> 7.18 | T6: =(MAX(N6:R6)-MIN(N6:R6))/(2*S6) -> 0.0097493036 | U6: ICP-F/MD | V6: QT SiO2 Etch-C4F8/O2 | W6: 2*5.25 min | X6: 45691 | Y6: Grace -AZ10xT onSiO2 on Si | AG6: 6.724 | AH6: 7.666 | AI6: 6.895 | AJ6: 7.276 | AK6: 7.484 | AL6: =AVERAGE(AG6:AK6) -> 7.209 | AM6: =(MAX(AG6:AK6)-MIN(AG6:AK6))/(2*AL6) -> 0.065334998 | AN6: SPTS-DRIE/MD | AO6: MD_DOE2_3x_-3 | AP6: 16.5 sccm | AQ6: 1295 | AR6: 45720 | AS6: MFF SiO2 on Si | AV6: 524 | AY6: 524 | BA6: 824.2 | BB6: 817.7 | BC6: 827.8 | BD6: =AVERAGE(BA6:BC6) -> 823.23333 | BE6: =(MAX(BA6:BC6)-MIN(BA6:BC6))/(2*BD6) -> 0.0061343483 | BF6: 727.6 | BG6: 724.9 | BH6: 730.3 | BI6: =AVERAGE(BF6:BH6) -> 727.6 | BJ6: =(MAX(BA6:BC6)-MIN(BA6:BC6))/(2*BD6) -> 0.0061343483 | BK6: 636.5 | BL6: 635 | BM6: 639.8 | BN6: =AVERAGE(BK6:BM6) -> 637.1 | BO6: =(MAX(BF6:BH6)-MIN(BF6:BH6))/(2*BI6) -> 0.0037108301 | BP6: 837.5 | BQ6: 762.6 | BR6: 680 | BS6: 221.5 | BT6: CW feature
A7: A11 | B7: 18. SEM | D7: 4033 | E7: 4236 | F7: 4091 | G7: 62.74 | H7: 2.5 | I7: 6.847 | J7: 7.451 | K7: 7.232 | L7: 0.1288 | M7: 4.2 | N7: 7.021 | O7: 7.204 | P7: 7.177 | Q7: 7.203 | R7: 7.234 | S7: =AVERAGE(N7:R7) -> 7.1678 | T7: =(MAX(N7:R7)-MIN(N7:R7))/(2*S7) -> 0.014858115 | U7: ICP-F/MD | V7: QT SiO2 Etch-C4F8/O2 | W7: 2*5.25 min | X7: 45698 | Y7: Grace -AZ10xT onSiO2 on Si | Z7: 1.5273 | AB7: 1.7365 | AC7: 1.712 | AE7: =AVERAGE(Z7:AD7) -> 1.6586 | AF7: =(MAX(Z7:AD7)-MIN(Z7:AD7))/(2*AE7) -> 0.063065236 | AG7: 6.156 | AH7: 6.367 | AI7: 6.266 | AJ7: 6.271 | AK7: 7.384 | AL7: =AVERAGE(AG7:AK7) -> 6.4888 | AM7: =(MAX(AG7:AK7)-MIN(AG7:AK7))/(2*AL7) -> 0.094624584 | AN7: SPTS-DRIE/MD | AO7: MD_DOE1_3x_-3 | AP7: 17.8 sccm | AQ7: 1295 | AR7: 45724 | AS7: MFF SiO2 on Si | AT7: 9.23 | AV7: 160.65 | AW7: 165.82 | AY7: =AVERAGE(AT7:AX7) -> 111.9 | AZ7: =(MAX(AT7:AX7)-MIN(AT7:AX7))/(2*AY7) -> 0.69968722 | BA7: 829.8 | BB7: 831.2 | BC7: 842.2 | BD7: =AVERAGE(BA7:BC7) -> 834.4 | BE7: =(MAX(BA7:BC7)-MIN(BA7:BC7))/(2*BD7) -> 0.007430489 | BF7: 744 | BG7: 746.3 | BH7: 751.4 | BI7: =AVERAGE(BF7:BH7) -> 747.23333 | BJ7: =(MAX(BA7:BC7)-MIN(BA7:BC7))/(2*BD7) -> 0.007430489 | BK7: 656.4 | BL7: 656 | BM7: 659.7 | BN7: =AVERAGE(BK7:BM7) -> 657.36667 | BO7: =(MAX(BF7:BH7)-MIN(BF7:BH7))/(2*BI7) -> 0.0049515992 | BT7: S feature
A8: A12 | B8: 18. SEM | D8: 4034 | E8: 4212 | F8: 4081 | G8: 50.49 | H8: 2.2 | I8: 6.893 | J8: 7.42 | K8: 7.222 | L8: 0.1156 | M8: 3.6 | N8: 6.986 | O8: 7.213 | P8: 7.135 | Q8: 7.208 | R8: 7.234 | S8: =AVERAGE(N8:R8) -> 7.1552 | T8: =(MAX(N8:R8)-MIN(N8:R8))/(2*S8) -> 0.017330054 | U8: ICP-F/MD | V8: QT SiO2 Etch-C4F8/O2 | W8: 2*5.25 min | X8: 45699 | Y8: Grace -AZ10xT onSiO2 on Si | Z8: 1.7451 | AA8: 1.8776 | AB8: 1.9382 | AC8: 1.9105 | AD8: 1.9377 | AE8: =AVERAGE(Z8:AD8) -> 1.88182 | AF8: =(MAX(Z8:AD8)-MIN(Z8:AD8))/(2*AE8) -> 0.051306714 | AG8: 6.305 | AH8: 6.401 | AI8: 6.449 | AJ8: 6.343 | AK8: 6.41 | AL8: =AVERAGE(AG8:AK8) -> 6.3816 | AM8: =(MAX(AG8:AK8)-MIN(AG8:AK8))/(2*AL8) -> 0.011282437 | AN8: SPTS-DRIE/MD | AO8: MD_DOE5_3x_-3 | AP8: 17.5 sccm | AQ8: 1295 | AR8: 45729 | AS8: MFF SiO2 on Si | AT8: 0 | AU8: 15.26 | AV8: 15.21 | AW8: 16.8 | AX8: 15.46 | AY8: =AVERAGE(AT8:AX8) -> 12.546 | AZ8: =(MAX(AT8:AX8)-MIN(AT8:AX8))/(2*AY8) -> 0.66953611 | BA8: 730.6 | BB8: 757.2 | BC8: 760 | BD8: =AVERAGE(BA8:BC8) -> 749.26667 | BE8: =(MAX(BA8:BC8)-MIN(BA8:BC8))/(2*BD8) -> 0.019619183 | BF8: 653.1 | BG8: 682.5 | BH8: 680.5 | BI8: =AVERAGE(BF8:BH8) -> 672.03333 | BJ8: =(MAX(BA8:BC8)-MIN(BA8:BC8))/(2*BD8) -> 0.019619183 | BK8: 567.7 | BL8: 599.6 | BM8: 594.7 | BN8: =AVERAGE(BK8:BM8) -> 587.33333 | BO8: =(MAX(BF8:BH8)-MIN(BF8:BH8))/(2*BI8) -> 0.021873915
A9: A13 | B9: 18. SEM | D9: 4034 | E9: 4247 | F9: 4091 | G9: 64.96 | H9: 2.6 | I9: 7.073 | J9: 7.464 | K9: 7.258 | L9: 0.1023 | M9: 2.7 | N9: 7.056 | O9: 7.223 | P9: 7.194 | Q9: 7.186 | R9: 7.292 | S9: =AVERAGE(N9:R9) -> 7.1902 | T9: =(MAX(N9:R9)-MIN(N9:R9))/(2*S9) -> 0.016411226 | U9: ICP-F/MD | V9: QT SiO2 Etch-C4F8/O2 | W9: 2*5.25 min | X9: 45699 | Y9: Grace -AZ10xT onSiO2 on Si | AG9: 7.05 | AH9: 7.217 | AI9: 7.058 | AJ9: 7.103 | AK9: 7.169 | AL9: =AVERAGE(AG9:AK9) -> 7.1194 | AM9: =(MAX(AG9:AK9)-MIN(AG9:AK9))/(2*AL9) -> 0.011728516 | AN9: SPTS-DRIE/MD | AO9: MD_DOE7_3x_-3 | AP9: 17.3 sccm | AQ9: 1295 | AR9: 45722 | AS9: MFF SiO2 on Si | AT9: 321.3 | AV9: 476.24 | AW9: 485.62 | AY9: =AVERAGE(AT9:AX9) -> 427.72 | AZ9: =(MAX(AT9:AX9)-MIN(AT9:AX9))/(2*AY9) -> 0.19208828 | BA9: 823.5 | BB9: 816.5 | BC9: 826.4 | BD9: =AVERAGE(BA9:BC9) -> 822.13333 | BE9: =(MAX(BA9:BC9)-MIN(BA9:BC9))/(2*BD9) -> 0.0060209212 | BF9: 733.6 | BG9: 732.3 | BH9: 737.7 | BI9: =AVERAGE(BF9:BH9) -> 734.53333 | BJ9: =(MAX(BA9:BC9)-MIN(BA9:BC9))/(2*BD9) -> 0.0060209212 | BK9: 640.4 | BL9: 638.3 | BM9: 644.7 | BN9: =AVERAGE(BK9:BM9) -> 641.13333 | BO9: =(MAX(BF9:BH9)-MIN(BF9:BH9))/(2*BI9) -> 0.0036758032
A10: A14 | B10: 18. SEM | D10: 3938 | E10: 4090 | F10: 3985 | G10: 41.17 | H10: 1.9 | I10: 6.814 | J10: 7.397 | K10: 7.17 | L10: 0.1542 | M10: 4.1 | N10: 7.124 | O10: 7.243 | P10: 7.239 | Q10: 7.313 | R10: 7.271 | S10: =AVERAGE(N10:R10) -> 7.238 | T10: =(MAX(N10:R10)-MIN(N10:R10))/(2*S10) -> 0.013056093 | U10: ICP-F/MD | V10: QT SiO2 Etch-C4F8/O2 | W10: 2*5.25 min | X10: 45699 | Y10: Grace -AZ10xT onSiO2 on Si | AG10: 4.605 | AH10: 4.429 | AI10: 4.489 | AJ10: 4.403 | AK10: 4.343 | AL10: =AVERAGE(AG10:AK10) -> 4.4538 | AM10: =(MAX(AG10:AK10)-MIN(AG10:AK10))/(2*AL10) -> 0.029413085 | AN10: SPTS-DRIE/MD | AO10: MD_DOE4_3x_-3 | AP10: 15.8 sccm | AQ10: 1295 | AR10: 45732 | AS10: MFF SiO2 on Si | AT10: 0 | AU10: 110.09 | AV10: 0 | AW10: 0 | AX10: 0 | AY10: =AVERAGE(AT10:AX10) -> 22.018 | AZ10: =(MAX(AT10:AX10)-MIN(AT10:AX10))/(2*AY10) -> 2.5 | BA10: 697.1 | BB10: 696.7 | BC10: 706 | BD10: =AVERAGE(BA10:BC10) -> 699.93333 | BE10: =(MAX(BA10:BC10)-MIN(BA10:BC10))/(2*BD10) -> 0.0066434899 | BF10: 610.3 | BG10: 615.9 | BH10: 621.1 | BI10: =AVERAGE(BF10:BH10) -> 615.76667 | BJ10: =(MAX(BA10:BC10)-MIN(BA10:BC10))/(2*BD10) -> 0.0066434899 | BK10: 515.7 | BL10: 520.8 | BM10: 529.3 | BN10: =AVERAGE(BK10:BM10) -> 521.93333 | BO10: =(MAX(BF10:BH10)-MIN(BF10:BH10))/(2*BI10) -> 0.0087695556
A11: A15 | B11: 18. SEM | D11: 3926 | E11: 4039 | F11: 3953 | G11: 22.61 | H11: 1.4 | I11: 7.022 | J11: 7.252 | K11: 7.186 | L11: 0.06452 | M11: 1.6 | N11: 7.317 | O11: 7.254 | P11: 7.571 | Q11: 7.442 | R11: 7.322 | S11: =AVERAGE(N11:R11) -> 7.3812 | T11: =(MAX(N11:R11)-MIN(N11:R11))/(2*S11) -> 0.021473473 | U11: ICP-F/MD | V11: QT SiO2 Etch-C4F8/O2 | W11: 3*3.5 min | X11: 45704 | Y11: Grace -AZ10xT onSiO2 on Si | Z11: 1.5678 | AA11: 1.7647 | AB11: 1.7057 | AC11: 1.7416 | AE11: =AVERAGE(Z11:AD11) -> 1.69495 | AF11: =(MAX(Z11:AD11)-MIN(Z11:AD11))/(2*AE11) -> 0.058084309 | AG11: 6.204 | AH11: 6.238 | AI11: 6.349 | AJ11: 6.38 | AK11: 6.563 | AL11: =AVERAGE(AG11:AK11) -> 6.3468 | AM11: =(MAX(AG11:AK11)-MIN(AG11:AK11))/(2*AL11) -> 0.028281969 | AN11: SPTS-DRIE/MD | AO11: MD_DOE6_3x_-3 | AP11: 16.1 sccm | AQ11: 1295 | AR11: 45732 | AS11: MFF SiO2 on Si | AT11: 0 | AU11: 0 | AV11: 0 | AW11: 0 | AX11: 27.7 | AY11: =AVERAGE(AT11:AX11) -> 5.54 | AZ11: =(MAX(AT11:AX11)-MIN(AT11:AX11))/(2*AY11) -> 2.5 | BA11: 679.5 | BB11: 704.6 | BC11: 704.9 | BD11: =AVERAGE(BA11:BC11) -> 696.33333 | BE11: =(MAX(BA11:BC11)-MIN(BA11:BC11))/(2*BD11) -> 0.018238392 | BF11: 603 | BG11: 633.3 | BH11: 626.1 | BI11: =AVERAGE(BF11:BH11) -> 620.8 | BJ11: =(MAX(BA11:BC11)-MIN(BA11:BC11))/(2*BD11) -> 0.018238392 | BK11: 518.7 | BL11: 551.2 | BM11: 540.8 | BN11: =AVERAGE(BK11:BM11) -> 536.9 | BO11: =(MAX(BF11:BH11)-MIN(BF11:BH11))/(2*BI11) -> 0.024403995
A12: A16 | B12: 18. SEM | D12: 4025 | E12: 4126 | F12: 4049 | G12: 19.75 | H12: 1.2 | I12: 7.067 | J12: 7.597 | K12: 7.255 | L12: 0.1258 | M12: 3.6 | N12: 7.331 | O12: 7.553 | P12: 7.596 | Q12: 7.346 | R12: 7.357 | S12: =AVERAGE(N12:R12) -> 7.4366 | T12: =(MAX(N12:R12)-MIN(N12:R12))/(2*S12) -> 0.017817282 | U12: ICP-F/MD | V12: QT SiO2 Etch-C4F8/O2 | W12: 3*3.5 min | X12: 45704 | Y12: Grace -AZ10xT onSiO2 on Si | AG12: 6.951 | AH12: 7.454 | AI12: 7.15 | AJ12: 7.2 | AK12: 7.127 | AL12: =AVERAGE(AG12:AK12) -> 7.1764 | AM12: =(MAX(AG12:AK12)-MIN(AG12:AK12))/(2*AL12) -> 0.035045427 | AN12: SPTS-DRIE/MD | AO12: MD_DOE8_3x_-3 | AP12: 16.9 sccm | AQ12: 1295 | AR12: 45730 | AS12: MFF SiO2 on Si | AT12: 132.89 | AV12: 50.44 | AY12: =AVERAGE(AT12:AX12) -> 91.665 | AZ12: =(MAX(AT12:AX12)-MIN(AT12:AX12))/(2*AY12) -> 0.44973545 | BA12: 738.4 | BB12: 625.3 | BC12: 737.6 | BD12: =AVERAGE(BA12:BC12) -> 700.43333 | BE12: =(MAX(BA12:BC12)-MIN(BA12:BC12))/(2*BD12) -> 0.080735735 | BF12: 662.4 | BG12: 561.7 | BH12: 661.5 | BI12: =AVERAGE(BF12:BH12) -> 628.53333 | BJ12: =(MAX(BA12:BC12)-MIN(BA12:BC12))/(2*BD12) -> 0.080735735 | BK12: 578.6 | BL12: 484.3 | BM12: 579.1 | BN12: =AVERAGE(BK12:BM12) -> 547.33333 | BO12: =(MAX(BF12:BH12)-MIN(BF12:BH12))/(2*BI12) -> 0.080107128
Y16: =(S8-AE8)/(F8/1000)*6.5 -> 8.3991595

Sheet DOE
A1: Current variations from loop set to loop set:
B2: Set 1 | C2: Set 2 | D2: Set 3
A3: Dep time | B3: 1.2 | C3: 1.2-->1.4 | D3: 1.4
A4: Etch 1 time | B4: 1.2 | C4: 1.2-->1.5 | D4: 1.5
A6: Etch 1 HF Power | B6: 64-->70 | C6: 70-->80 | D6: 80-->60
A7: Etch 2 HF Power | B7: 24 | C7: 24 | D7: 20
A9: Dep HF Tune Capaciter | B9: 20 | C9: 25 | D9: 20
A10: Etch 1 HF Tune Capaciter | B10: 20 | C10: 25 | D10: 20
A11: Etch 2 HF Tune Capaciter | B11: 25 | C11: 20 | D11: 20
A12: Dep HF Load Capaciter | B12: 30 | C12: 25 | D12: 30
A13: Etch 1 HF Load Capaciter | B13: 30 | C13: 25 | D13: 30
A14: Etch 2 HF Load Capaciter | B14: 25 | C14: 30 | D14: 30

Sheet MM_Deep_3x_-3
A1: Recipe name | C1: MM_Deep_3x_-3
B2: Unit | C2: 1 | D2: 2 | E2: 3 | F2: 4 | G2: 5 | H2: 6 | I2: 7 | J2: 8 | K2: 9 | L2: 10
A3: Step name | C3: Strike 1 | D3: Dep 1 | E3: Etch 1_1 | F3: Etch 1_2 | G3: Dep 2 | H3: Etch 2_1 | I3: Etch 2_2 | J3: Dep 3 | K3: Etch 3_1 | L3: Etch 3_2
A4: Process Time | B4: secs | C4: 1 | D4: 1.2 | E4: 1.2 | F4: 2.5 2.5 | G4: 1.2 1.4 | H4: 1.2 1.5 | I4: 2.5 2.5 | J4: 1.4 1.4 | K4: 1.5 1.5 | L4: 2.5 2.5
A5: Process Pressure | B5: mTorr | C5: 40.0 +/- 0% | D5: 40.0 +/- 50% | E5: 30.0 30.0 +/- 50% | F5: 30.0 30.0 +/- 50% | G5: 40.0 40 +/- 50% | H5: 30.0 30 +/- 50% | I5: 30.0 30.0 +/- 50% | J5: 40.0 40.0 +/- 50% | K5: 30.0 30.0 +/- 50% | L5: 30.0 30.0 +/-50%
A6: APC Setpoint Position | B6: % | C6: 100 | D6: 100 | E6: 100 | F6: 100 | G6: 100 | H6: 100 | I6: 100 | J6: 100 | K6: 100 | L6: 100
A7: APC Mode | C7: Automatic | D7: Automatic | E7: Automatic | F7: Automatic | G7: Automatic | H7: Automatic | I7: Automatic | J7: Automatic | K7: Automatic | L7: Automatic
A8: Source power | B8: Watts | C8: 2500.0 +/- 0 | D8: 2500.0 +/- 50% | E8: 2500.0 +/- 50% | F8: 2500.0 +/- 50% | G8: 2500.0 2500 +/- 50% | H8: 2500.0 2500 +/- 50% | I8: 2500.0 2500 +/- 50% | J8: 2500.0 2500 +/- 50% | K8: 2500.0 2500 +/- 50% | L8: 2500.0 2500 +/- 50%
A9: Source MU Tune capaciter | C9: 4 | D9: 4 | E9: 4 | F9: 4 | G9: 4 | H9: 4 | I9: 4 | J9: 4 | K9: 4 | L9: 4
A10: Source MU load capaciter | C10: 2 | D10: 2 | E10: 2 | F10: 2 | G10: 2 | H10: 2 | I10: 2 | J10: 2 | K10: 2 | L10: 2
A11: Source RF Control Mode | C11: Load | D11: Load | E11: Load | F11: Load | G11: Load | H11: Load | I11: Load | J11: Load | K11: Load | L11: Load
A12: Source 2 Power | B12: Watts | C12: 500.0 +/- 0 | D12: 500.0 +/- 50% | E12: 500.0 +/- 50% | F12: 500.0 +/- 50% | G12: 500.0 500 +/- 50% | H12: 500.0 500 +/- 50% | I12: 500.0 500 +/- 50% | J12: 500.0 500 +/- 50% | K12: 500.0 500 +/- 50% | L12: 500.0 500 +/- 50%
